Workbook

Sheet Non-road summary
A1: Metadata
A2: GAINS IAM Model Release 4.0.3 (October 2023) (Greenhouse Gas - Air Pollution Interactions and Synergies)
A3: https://gains.iiasa.ac.at/models/gains_models4.html
A4: Data downloaded 10/14/24
A5: User jm110
A6: Scenario: ECLIPSE_V6b_CLE_base
A7: Region: All EMF Regions
A9: GWP values from AR5 WG1 Chapter 8 Supplemental (8SM) Table 8.SM.17
A10: Pollutant | B10: GWP20 | C10: GWP100
A11: BC | B11: 2421.1 | C11: 658.6
A12: CH4 | B12: 83.9 | C12: 28.5
A14: Definition of GAINS non-road sub-sectors
A15: Sub-sector | B15: Definition
A16: TRA_OT_CNS | B16: Mobile machines in construction and industry
A17: TRA_OT_AGR | B17: Tractors and mobile machines in agriculture and forestry
A18: TRA_OT_RAI | B18: Railways
A19: TRA_OT_SHIP_NAT | B19: Movement of ships between ports in the same country and fishing vessels
A20: TRA_OT_OTHER | B20: Vehicles and small machines with 2-stroke engines; civil aviation for domestic flights; and other non-road sources with 4-stroke engines, including household, forestry, military vehicles, motorboats, and gas by pipeline compressors
A22: CO2 emissions from non-road transport (Mt CO2) | P22: https://gains.iiasa.ac.at/gains/download/GAINS-tutorial.pdf
B23: 1990 | C23: 1995 | D23: 2000 | E23: 2005 | F23: 2010 | G23: 2015 | H23: 2020 | I23: 2025 | J23: 2030 | K23: 2035 | L23: 2040 | M23: 2045 | N23: 2050
A24: TRA_OT_CNS | B24: =SUMIF('Non-road CO2'!$B:$B,'Non-road summary'!$A24,'Non-road CO2'!C:C) -> 122 | C24: =SUMIF('Non-road CO2'!$B:$B,'Non-road summary'!$A24,'Non-road CO2'!D:D) -> 100.99 | D24: =SUMIF('Non-road CO2'!$B:$B,'Non-road summary'!$A24,'Non-road CO2'!E:E) -> 110.09 | E24: =SUMIF('Non-road CO2'!$B:$B,'Non-road summary'!$A24,'Non-road CO2'!F:F) -> 116 | F24: =SUMIF('Non-road CO2'!$B:$B,'Non-road summary'!$A24,'Non-road CO2'!G:G) -> 119.42 | G24: =SUMIF('Non-road CO2'!$B:$B,'Non-road summary'!$A24,'Non-road CO2'!H:H) -> 135.7 | H24: =SUMIF('Non-road CO2'!$B:$B,'Non-road summary'!$A24,'Non-road CO2'!I:I) -> 259.09 | I24: =SUMIF('Non-road CO2'!$B:$B,'Non-road summary'!$A24,'Non-road CO2'!J:J) -> 264.83 | J24: =SUMIF('Non-road CO2'!$B:$B,'Non-road summary'!$A24,'Non-road CO2'!K:K) -> 258.71 | K24: =SUMIF('Non-road CO2'!$B:$B,'Non-road summary'!$A24,'Non-road CO2'!L:L) -> 273.47 | L24: =SUMIF('Non-road CO2'!$B:$B,'Non-road summary'!$A24,'Non-road CO2'!M:M) -> 287.07 | M24: =SUMIF('Non-road CO2'!$B:$B,'Non-road summary'!$A24,'Non-road CO2'!N:N) -> 284.86 | N24: =SUMIF('Non-road CO2'!$B:$B,'Non-road summary'!$A24,'Non-road CO2'!O:O) -> 279.65
A25: TRA_OT_AGR | B25: =SUMIF('Non-road CO2'!$B:$B,'Non-road summary'!$A25,'Non-road CO2'!C:C) -> 218.22 | C25: =SUMIF('Non-road CO2'!$B:$B,'Non-road summary'!$A25,'Non-road CO2'!D:D) -> 227.75 | D25: =SUMIF('Non-road CO2'!$B:$B,'Non-road summary'!$A25,'Non-road CO2'!E:E) -> 201.59 | E25: =SUMIF('Non-road CO2'!$B:$B,'Non-road summary'!$A25,'Non-road CO2'!F:F) -> 227.26 | F25: =SUMIF('Non-road CO2'!$B:$B,'Non-road summary'!$A25,'Non-road CO2'!G:G) -> 227.06 | G25: =SUMIF('Non-road CO2'!$B:$B,'Non-road summary'!$A25,'Non-road CO2'!H:H) -> 222.61 | H25: =SUMIF('Non-road CO2'!$B:$B,'Non-road summary'!$A25,'Non-road CO2'!I:I) -> 244.1 | I25: =SUMIF('Non-road CO2'!$B:$B,'Non-road summary'!$A25,'Non-road CO2'!J:J) -> 245.81 | J25: =SUMIF('Non-road CO2'!$B:$B,'Non-road summary'!$A25,'Non-road CO2'!K:K) -> 241.81 | K25: =SUMIF('Non-road CO2'!$B:$B,'Non-road summary'!$A25,'Non-road CO2'!L:L) -> 236.74 | L25: =SUMIF('Non-road CO2'!$B:$B,'Non-road summary'!$A25,'Non-road CO2'!M:M) -> 232.24 | M25: =SUMIF('Non-road CO2'!$B:$B,'Non-road summary'!$A25,'Non-road CO2'!N:N) -> 229.91 | N25: =SUMIF('Non-road CO2'!$B:$B,'Non-road summary'!$A25,'Non-road CO2'!O:O) -> 221.23
A26: TRA_OT_RAI | B26: =SUMIF('Non-road CO2'!$B:$B,'Non-road summary'!$A26,'Non-road CO2'!C:C) -> 92.03 | C26: =SUMIF('Non-road CO2'!$B:$B,'Non-road summary'!$A26,'Non-road CO2'!D:D) -> 74.01 | D26: =SUMIF('Non-road CO2'!$B:$B,'Non-road summary'!$A26,'Non-road CO2'!E:E) -> 82.09 | E26: =SUMIF('Non-road CO2'!$B:$B,'Non-road summary'!$A26,'Non-road CO2'!F:F) -> 98.26 | F26: =SUMIF('Non-road CO2'!$B:$B,'Non-road summary'!$A26,'Non-road CO2'!G:G) -> 82.94 | G26: =SUMIF('Non-road CO2'!$B:$B,'Non-road summary'!$A26,'Non-road CO2'!H:H) -> 90.4 | H26: =SUMIF('Non-road CO2'!$B:$B,'Non-road summary'!$A26,'Non-road CO2'!I:I) -> 82.05 | I26: =SUMIF('Non-road CO2'!$B:$B,'Non-road summary'!$A26,'Non-road CO2'!J:J) -> 77.59 | J26: =SUMIF('Non-road CO2'!$B:$B,'Non-road summary'!$A26,'Non-road CO2'!K:K) -> 73.8 | K26: =SUMIF('Non-road CO2'!$B:$B,'Non-road summary'!$A26,'Non-road CO2'!L:L) -> 70.4 | L26: =SUMIF('Non-road CO2'!$B:$B,'Non-road summary'!$A26,'Non-road CO2'!M:M) -> 66.31 | M26: =SUMIF('Non-road CO2'!$B:$B,'Non-road summary'!$A26,'Non-road CO2'!N:N) -> 61.24 | N26: =SUMIF('Non-road CO2'!$B:$B,'Non-road summary'!$A26,'Non-road CO2'!O:O) -> 55.17
A27: TRA_OT_SHIP_NAT | B27: =SUMIF('Non-road CO2'!$B:$B,'Non-road summary'!$A27,'Non-road CO2'!C:C) -> 74.87 | C27: =SUMIF('Non-road CO2'!$B:$B,'Non-road summary'!$A27,'Non-road CO2'!D:D) -> 61.53 | D27: =SUMIF('Non-road CO2'!$B:$B,'Non-road summary'!$A27,'Non-road CO2'!E:E) -> 129.96 | E27: =SUMIF('Non-road CO2'!$B:$B,'Non-road summary'!$A27,'Non-road CO2'!F:F) -> 140.41 | F27: =SUMIF('Non-road CO2'!$B:$B,'Non-road summary'!$A27,'Non-road CO2'!G:G) -> 146.93 | G27: =SUMIF('Non-road CO2'!$B:$B,'Non-road summary'!$A27,'Non-road CO2'!H:H) -> 180.01 | H27: =SUMIF('Non-road CO2'!$B:$B,'Non-road summary'!$A27,'Non-road CO2'!I:I) -> 169.28 | I27: =SUMIF('Non-road CO2'!$B:$B,'Non-road summary'!$A27,'Non-road CO2'!J:J) -> 185.68 | J27: =SUMIF('Non-road CO2'!$B:$B,'Non-road summary'!$A27,'Non-road CO2'!K:K) -> 199.43 | K27: =SUMIF('Non-road CO2'!$B:$B,'Non-road summary'!$A27,'Non-road CO2'!L:L) -> 210.09 | L27: =SUMIF('Non-road CO2'!$B:$B,'Non-road summary'!$A27,'Non-road CO2'!M:M) -> 216.53 | M27: =SUMIF('Non-road CO2'!$B:$B,'Non-road summary'!$A27,'Non-road CO2'!N:N) -> 218.22 | N27: =SUMIF('Non-road CO2'!$B:$B,'Non-road summary'!$A27,'Non-road CO2'!O:O) -> 213.11
A28: TRA_OT_OTHER | B28: =SUMIF('Non-road CO2'!$B:$B,'Non-road summary'!$A28,'Non-road CO2'!C:C) -> 311.24 | C28: =SUMIF('Non-road CO2'!$B:$B,'Non-road summary'!$A28,'Non-road CO2'!D:D) -> 284.69 | D28: =SUMIF('Non-road CO2'!$B:$B,'Non-road summary'!$A28,'Non-road CO2'!E:E) -> 309.03 | E28: =SUMIF('Non-road CO2'!$B:$B,'Non-road summary'!$A28,'Non-road CO2'!F:F) -> 327.79 | F28: =SUMIF('Non-road CO2'!$B:$B,'Non-road summary'!$A28,'Non-road CO2'!G:G) -> 332.55 | G28: =SUMIF('Non-road CO2'!$B:$B,'Non-road summary'!$A28,'Non-road CO2'!H:H) -> 378.04 | H28: =SUMIF('Non-road CO2'!$B:$B,'Non-road summary'!$A28,'Non-road CO2'!I:I) -> 380.94 | I28: =SUMIF('Non-road CO2'!$B:$B,'Non-road summary'!$A28,'Non-road CO2'!J:J) -> 408.63 | J28: =SUMIF('Non-road CO2'!$B:$B,'Non-road summary'!$A28,'Non-road CO2'!K:K) -> 443.57 | K28: =SUMIF('Non-road CO2'!$B:$B,'Non-road summary'!$A28,'Non-road CO2'!L:L) -> 483.8 | L28: =SUMIF('Non-road CO2'!$B:$B,'Non-road summary'!$A28,'Non-road CO2'!M:M) -> 530 | M28: =SUMIF('Non-road CO2'!$B:$B,'Non-road summary'!$A28,'Non-road CO2'!N:N) -> 579.66 | N28: =SUMIF('Non-road CO2'!$B:$B,'Non-road summary'!$A28,'Non-road CO2'!O:O) -> 631.17
A29: SUM | B29: =SUMIF('Non-road CO2'!$B:$B,'Non-road summary'!$A29,'Non-road CO2'!C:C) -> 818.32 | C29: =SUMIF('Non-road CO2'!$B:$B,'Non-road summary'!$A29,'Non-road CO2'!D:D) -> 748.94 | D29: =SUMIF('Non-road CO2'!$B:$B,'Non-road summary'!$A29,'Non-road CO2'!E:E) -> 832.75 | E29: =SUMIF('Non-road CO2'!$B:$B,'Non-road summary'!$A29,'Non-road CO2'!F:F) -> 909.7 | F29: =SUMIF('Non-road CO2'!$B:$B,'Non-road summary'!$A29,'Non-road CO2'!G:G) -> 908.91 | G29: =SUMIF('Non-road CO2'!$B:$B,'Non-road summary'!$A29,'Non-road CO2'!H:H) -> 1006.77 | H29: =SUMIF('Non-road CO2'!$B:$B,'Non-road summary'!$A29,'Non-road CO2'!I:I) -> 1135.42 | I29: =SUMIF('Non-road CO2'!$B:$B,'Non-road summary'!$A29,'Non-road CO2'!J:J) -> 1182.52 | J29: =SUMIF('Non-road CO2'!$B:$B,'Non-road summary'!$A29,'Non-road CO2'!K:K) -> 1217.35 | K29: =SUMIF('Non-road CO2'!$B:$B,'Non-road summary'!$A29,'Non-road CO2'!L:L) -> 1274.47 | L29: =SUMIF('Non-road CO2'!$B:$B,'Non-road summary'!$A29,'Non-road CO2'!M:M) -> 1332.15 | M29: =SUMIF('Non-road CO2'!$B:$B,'Non-road summary'!$A29,'Non-road CO2'!N:N) -> 1373.94 | N29: =SUMIF('Non-road CO2'!$B:$B,'Non-road summary'!$A29,'Non-road CO2'!O:O) -> 1400.33
A30: ALL SUM | B30: ='Non-road CO2'!C186 -> 818.33 | C30: ='Non-road CO2'!D186 -> 748.95 | D30: ='Non-road CO2'!E186 -> 832.72 | E30: ='Non-road CO2'!F186 -> 909.72 | F30: ='Non-road CO2'!G186 -> 908.91 | G30: ='Non-road CO2'!H186 -> 1006.77 | H30: ='Non-road CO2'!I186 -> 1135.43 | I30: ='Non-road CO2'!J186 -> 1182.51 | ... N30: ='Non-road CO2'!O186 -> 1400.34
A32: BC emissions from non-road transport (kt PM)
B33: 1990 | C33: 1995 | D33: 2000 | E33: 2005 | F33: 2010 | G33: 2015 | H33: 2020 | I33: 2025 | J33: 2030 | K33: 2035 | L33: 2040 | M33: 2045 | N33: 2050
A34: TRA_OT_CNS | B34: =SUMIF('Non-road BC'!$B:$B,'Non-road summary'!$A34,'Non-road BC'!C:C) -> 98.19 | C34: =SUMIF('Non-road BC'!$B:$B,'Non-road summary'!$A34,'Non-road BC'!D:D) -> 82.21 | D34: =SUMIF('Non-road BC'!$B:$B,'Non-road summary'!$A34,'Non-road BC'!E:E) -> 88.79 | E34: =SUMIF('Non-road BC'!$B:$B,'Non-road summary'!$A34,'Non-road BC'!F:F) -> 86.46 | F34: =SUMIF('Non-road BC'!$B:$B,'Non-road summary'!$A34,'Non-road BC'!G:G) -> 84.62 | G34: =SUMIF('Non-road BC'!$B:$B,'Non-road summary'!$A34,'Non-road BC'!H:H) -> 82.66 | H34: =SUMIF('Non-road BC'!$B:$B,'Non-road summary'!$A34,'Non-road BC'!I:I) -> 115.69 | I34: =SUMIF('Non-road BC'!$B:$B,'Non-road summary'!$A34,'Non-road BC'!J:J) -> 103.7 | J34: =SUMIF('Non-road BC'!$B:$B,'Non-road summary'!$A34,'Non-road BC'!K:K) -> 93.89 | K34: =SUMIF('Non-road BC'!$B:$B,'Non-road summary'!$A34,'Non-road BC'!L:L) -> 99.9 | L34: =SUMIF('Non-road BC'!$B:$B,'Non-road summary'!$A34,'Non-road BC'!M:M) -> 105.81 | M34: =SUMIF('Non-road BC'!$B:$B,'Non-road summary'!$A34,'Non-road BC'!N:N) -> 105.41 | N34: =SUMIF('Non-road BC'!$B:$B,'Non-road summary'!$A34,'Non-road BC'!O:O) -> 104.79
A35: TRA_OT_AGR | B35: =SUMIF('Non-road BC'!$B:$B,'Non-road summary'!$A35,'Non-road BC'!C:C) -> 148.32 | C35: =SUMIF('Non-road BC'!$B:$B,'Non-road summary'!$A35,'Non-road BC'!D:D) -> 156.19 | D35: =SUMIF('Non-road BC'!$B:$B,'Non-road summary'!$A35,'Non-road BC'!E:E) -> 140.44 | E35: =SUMIF('Non-road BC'!$B:$B,'Non-road summary'!$A35,'Non-road BC'!F:F) -> 148.52 | F35: =SUMIF('Non-road BC'!$B:$B,'Non-road summary'!$A35,'Non-road BC'!G:G) -> 140.75 | G35: =SUMIF('Non-road BC'!$B:$B,'Non-road summary'!$A35,'Non-road BC'!H:H) -> 124.82 | H35: =SUMIF('Non-road BC'!$B:$B,'Non-road summary'!$A35,'Non-road BC'!I:I) -> 104.56 | I35: =SUMIF('Non-road BC'!$B:$B,'Non-road summary'!$A35,'Non-road BC'!J:J) -> 93.27 | J35: =SUMIF('Non-road BC'!$B:$B,'Non-road summary'!$A35,'Non-road BC'!K:K) -> 86.95 | K35: =SUMIF('Non-road BC'!$B:$B,'Non-road summary'!$A35,'Non-road BC'!L:L) -> 84.02 | L35: =SUMIF('Non-road BC'!$B:$B,'Non-road summary'!$A35,'Non-road BC'!M:M) -> 81.85 | M35: =SUMIF('Non-road BC'!$B:$B,'Non-road summary'!$A35,'Non-road BC'!N:N) -> 80.22 | N35: =SUMIF('Non-road BC'!$B:$B,'Non-road summary'!$A35,'Non-road BC'!O:O) -> 77.93
A36: TRA_OT_RAI | B36: =SUMIF('Non-road BC'!$B:$B,'Non-road summary'!$A36,'Non-road BC'!C:C) -> 54.66 | C36: =SUMIF('Non-road BC'!$B:$B,'Non-road summary'!$A36,'Non-road BC'!D:D) -> 44.03 | D36: =SUMIF('Non-road BC'!$B:$B,'Non-road summary'!$A36,'Non-road BC'!E:E) -> 48.81 | E36: =SUMIF('Non-road BC'!$B:$B,'Non-road summary'!$A36,'Non-road BC'!F:F) -> 56.54 | F36: =SUMIF('Non-road BC'!$B:$B,'Non-road summary'!$A36,'Non-road BC'!G:G) -> 46.19 | G36: =SUMIF('Non-road BC'!$B:$B,'Non-road summary'!$A36,'Non-road BC'!H:H) -> 44.49 | H36: =SUMIF('Non-road BC'!$B:$B,'Non-road summary'!$A36,'Non-road BC'!I:I) -> 35.66 | I36: =SUMIF('Non-road BC'!$B:$B,'Non-road summary'!$A36,'Non-road BC'!J:J) -> 30.29 | J36: =SUMIF('Non-road BC'!$B:$B,'Non-road summary'!$A36,'Non-road BC'!K:K) -> 27.55 | K36: =SUMIF('Non-road BC'!$B:$B,'Non-road summary'!$A36,'Non-road BC'!L:L) -> 25.7 | L36: =SUMIF('Non-road BC'!$B:$B,'Non-road summary'!$A36,'Non-road BC'!M:M) -> 25.31 | M36: =SUMIF('Non-road BC'!$B:$B,'Non-road summary'!$A36,'Non-road BC'!N:N) -> 24.5 | N36: =SUMIF('Non-road BC'!$B:$B,'Non-road summary'!$A36,'Non-road BC'!O:O) -> 22.9
A37: TRA_OT_SHIP_NAT | B37: =SUMIF('Non-road BC'!$B:$B,'Non-road summary'!$A37,'Non-road BC'!C:C) -> 27.88 | C37: =SUMIF('Non-road BC'!$B:$B,'Non-road summary'!$A37,'Non-road BC'!D:D) -> 23.29 | D37: =SUMIF('Non-road BC'!$B:$B,'Non-road summary'!$A37,'Non-road BC'!E:E) -> 67.73 | E37: =SUMIF('Non-road BC'!$B:$B,'Non-road summary'!$A37,'Non-road BC'!F:F) -> 72.71 | F37: =SUMIF('Non-road BC'!$B:$B,'Non-road summary'!$A37,'Non-road BC'!G:G) -> 76.66 | G37: =SUMIF('Non-road BC'!$B:$B,'Non-road summary'!$A37,'Non-road BC'!H:H) -> 94.26 | H37: =SUMIF('Non-road BC'!$B:$B,'Non-road summary'!$A37,'Non-road BC'!I:I) -> 85.66 | I37: =SUMIF('Non-road BC'!$B:$B,'Non-road summary'!$A37,'Non-road BC'!J:J) -> 93.98 | J37: =SUMIF('Non-road BC'!$B:$B,'Non-road summary'!$A37,'Non-road BC'!K:K) -> 100.64 | K37: =SUMIF('Non-road BC'!$B:$B,'Non-road summary'!$A37,'Non-road BC'!L:L) -> 106.99 | L37: =SUMIF('Non-road BC'!$B:$B,'Non-road summary'!$A37,'Non-road BC'!M:M) -> 110.91 | M37: =SUMIF('Non-road BC'!$B:$B,'Non-road summary'!$A37,'Non-road BC'!N:N) -> 112.66 | N37: =SUMIF('Non-road BC'!$B:$B,'Non-road summary'!$A37,'Non-road BC'!O:O) -> 110.31
A38: TRA_OT_OTHER | B38: =SUMIF('Non-road BC'!$B:$B,'Non-road summary'!$A38,'Non-road BC'!C:C) -> 16.97 | C38: =SUMIF('Non-road BC'!$B:$B,'Non-road summary'!$A38,'Non-road BC'!D:D) -> 7.55 | D38: =SUMIF('Non-road BC'!$B:$B,'Non-road summary'!$A38,'Non-road BC'!E:E) -> 5.93 | E38: =SUMIF('Non-road BC'!$B:$B,'Non-road summary'!$A38,'Non-road BC'!F:F) -> 8.47 | F38: =SUMIF('Non-road BC'!$B:$B,'Non-road summary'!$A38,'Non-road BC'!G:G) -> 8.88 | G38: =SUMIF('Non-road BC'!$B:$B,'Non-road summary'!$A38,'Non-road BC'!H:H) -> 8.91 | H38: =SUMIF('Non-road BC'!$B:$B,'Non-road summary'!$A38,'Non-road BC'!I:I) -> 6.99 | I38: =SUMIF('Non-road BC'!$B:$B,'Non-road summary'!$A38,'Non-road BC'!J:J) -> 6.22 | J38: =SUMIF('Non-road BC'!$B:$B,'Non-road summary'!$A38,'Non-road BC'!K:K) -> 5.62 | K38: =SUMIF('Non-road BC'!$B:$B,'Non-road summary'!$A38,'Non-road BC'!L:L) -> 5.22 | L38: =SUMIF('Non-road BC'!$B:$B,'Non-road summary'!$A38,'Non-road BC'!M:M) -> 5.02 | M38: =SUMIF('Non-road BC'!$B:$B,'Non-road summary'!$A38,'Non-road BC'!N:N) -> 4.92 | N38: =SUMIF('Non-road BC'!$B:$B,'Non-road summary'!$A38,'Non-road BC'!O:O) -> 4.93
A39: SUM | B39: =SUMIF('Non-road BC'!$B:$B,'Non-road summary'!$A39,'Non-road BC'!C:C) -> 346.04 | C39: =SUMIF('Non-road BC'!$B:$B,'Non-road summary'!$A39,'Non-road BC'!D:D) -> 313.31 | D39: =SUMIF('Non-road BC'!$B:$B,'Non-road summary'!$A39,'Non-road BC'!E:E) -> 351.75 | E39: =SUMIF('Non-road BC'!$B:$B,'Non-road summary'!$A39,'Non-road BC'!F:F) -> 372.65 | F39: =SUMIF('Non-road BC'!$B:$B,'Non-road summary'!$A39,'Non-road BC'!G:G) -> 357.11 | G39: =SUMIF('Non-road BC'!$B:$B,'Non-road summary'!$A39,'Non-road BC'!H:H) -> 355.13 | H39: =SUMIF('Non-road BC'!$B:$B,'Non-road summary'!$A39,'Non-road BC'!I:I) -> 348.57 | I39: =SUMIF('Non-road BC'!$B:$B,'Non-road summary'!$A39,'Non-road BC'!J:J) -> 327.48 | J39: =SUMIF('Non-road BC'!$B:$B,'Non-road summary'!$A39,'Non-road BC'!K:K) -> 314.7 | K39: =SUMIF('Non-road BC'!$B:$B,'Non-road summary'!$A39,'Non-road BC'!L:L) -> 321.89 | L39: =SUMIF('Non-road BC'!$B:$B,'Non-road summary'!$A39,'Non-road BC'!M:M) -> 328.88 | M39: =SUMIF('Non-road BC'!$B:$B,'Non-road summary'!$A39,'Non-road BC'!N:N) -> 327.72 | N39: =SUMIF('Non-road BC'!$B:$B,'Non-road summary'!$A39,'Non-road BC'!O:O) -> 320.87
A40: ALL SUM | B40: ='Non-road BC'!C186 -> 346.04 | C40: ='Non-road BC'!D186 -> 313.32 | D40: ='Non-road BC'!E186 -> 351.77 | E40: ='Non-road BC'!F186 -> 372.67 | F40: ='Non-road BC'!G186 -> 357.11 | G40: ='Non-road BC'!H186 -> 355.13 | H40: ='Non-road BC'!I186 -> 348.57 | I40: ='Non-road BC'!J186 -> 327.47 | ... N40: ='Non-road BC'!O186 -> 320.86
A42: CH4 emissions from non-road transport (kt CH4)
B43: 1990 | C43: 1995 | D43: 2000 | E43: 2005 | F43: 2010 | G43: 2015 | H43: 2020 | I43: 2025 | J43: 2030 | K43: 2035 | L43: 2040 | M43: 2045 | N43: 2050
A44: TRA_OT_CNS | B44: =SUMIF('Non-road CH4'!$B:$B,'Non-road summary'!$A44,'Non-road CH4'!C:C) -> 6.91 | C44: =SUMIF('Non-road CH4'!$B:$B,'Non-road summary'!$A44,'Non-road CH4'!D:D) -> 5.7 | D44: =SUMIF('Non-road CH4'!$B:$B,'Non-road summary'!$A44,'Non-road CH4'!E:E) -> 6.24 | E44: =SUMIF('Non-road CH4'!$B:$B,'Non-road summary'!$A44,'Non-road CH4'!F:F) -> 6.57 | F44: =SUMIF('Non-road CH4'!$B:$B,'Non-road summary'!$A44,'Non-road CH4'!G:G) -> 6.86 | G44: =SUMIF('Non-road CH4'!$B:$B,'Non-road summary'!$A44,'Non-road CH4'!H:H) -> 7.88 | H44: =SUMIF('Non-road CH4'!$B:$B,'Non-road summary'!$A44,'Non-road CH4'!I:I) -> 15.11 | I44: =SUMIF('Non-road CH4'!$B:$B,'Non-road summary'!$A44,'Non-road CH4'!J:J) -> 15.5 | J44: =SUMIF('Non-road CH4'!$B:$B,'Non-road summary'!$A44,'Non-road CH4'!K:K) -> 15.34 | K44: =SUMIF('Non-road CH4'!$B:$B,'Non-road summary'!$A44,'Non-road CH4'!L:L) -> 16.27 | L44: =SUMIF('Non-road CH4'!$B:$B,'Non-road summary'!$A44,'Non-road CH4'!M:M) -> 17.22 | M44: =SUMIF('Non-road CH4'!$B:$B,'Non-road summary'!$A44,'Non-road CH4'!N:N) -> 17.14 | N44: =SUMIF('Non-road CH4'!$B:$B,'Non-road summary'!$A44,'Non-road CH4'!O:O) -> 16.88
A45: TRA_OT_AGR | B45: =SUMIF('Non-road CH4'!$B:$B,'Non-road summary'!$A45,'Non-road CH4'!C:C) -> 12.32 | C45: =SUMIF('Non-road CH4'!$B:$B,'Non-road summary'!$A45,'Non-road CH4'!D:D) -> 12.84 | D45: =SUMIF('Non-road CH4'!$B:$B,'Non-road summary'!$A45,'Non-road CH4'!E:E) -> 11.38 | E45: =SUMIF('Non-road CH4'!$B:$B,'Non-road summary'!$A45,'Non-road CH4'!F:F) -> 12.88 | F45: =SUMIF('Non-road CH4'!$B:$B,'Non-road summary'!$A45,'Non-road CH4'!G:G) -> 13.13 | G45: =SUMIF('Non-road CH4'!$B:$B,'Non-road summary'!$A45,'Non-road CH4'!H:H) -> 13.03 | H45: =SUMIF('Non-road CH4'!$B:$B,'Non-road summary'!$A45,'Non-road CH4'!I:I) -> 14.3 | I45: =SUMIF('Non-road CH4'!$B:$B,'Non-road summary'!$A45,'Non-road CH4'!J:J) -> 14.48 | J45: =SUMIF('Non-road CH4'!$B:$B,'Non-road summary'!$A45,'Non-road CH4'!K:K) -> 14.33 | K45: =SUMIF('Non-road CH4'!$B:$B,'Non-road summary'!$A45,'Non-road CH4'!L:L) -> 14.08 | L45: =SUMIF('Non-road CH4'!$B:$B,'Non-road summary'!$A45,'Non-road CH4'!M:M) -> 13.83 | M45: =SUMIF('Non-road CH4'!$B:$B,'Non-road summary'!$A45,'Non-road CH4'!N:N) -> 13.76 | N45: =SUMIF('Non-road CH4'!$B:$B,'Non-road summary'!$A45,'Non-road CH4'!O:O) -> 13.3
...

Sheet Agg
A1: Scenario | B1: Sector | C1: Source | D1: Species | E1: Units | F1: 2020 | G1: 2021 | H1: 2022 | I1: 2023 | J1: 2024 | K1: 2025 | L1: 2026 | M1: 2027 | N1: 2028 | O1: 2029 | P1: 2030 | Q1: 2031 | R1: 2032 | S1: 2033 | T1: 2034 | U1: 2035 | V1: 2036 | W1: 2037 | X1: 2038 | Y1: 2039 | Z1: 2040 | AA1: 2041 | AB1: 2042 | AC1: 2043 | AD1: 2044 | AE1: 2045 | AF1: 2046 | AG1: 2047 | AH1: 2048 | AI1: 2049 | AJ1: 2050
A2: BAU | B2: off-road | C2: TTW | D2: co2 | E2: Mt | F2: ='Non-road summary'!H29 -> 1135.42 | G2: =($K2-$F2)/5*(G$1-$F$1)+$F2 -> 1144.84 | H2: =($K2-$F2)/5*(H$1-$F$1)+$F2 -> 1154.26 | I2: =($K2-$F2)/5*(I$1-$F$1)+$F2 -> 1163.68 | J2: =($K2-$F2)/5*(J$1-$F$1)+$F2 -> 1173.1 | K2: ='Non-road summary'!I29 -> 1182.52 | L2: =($P2-$K2)/5*(L$1-$K$1)+$K2 -> 1189.486 | M2: =($P2-$K2)/5*(M$1-$K$1)+$K2 -> 1196.452 | N2: =($P2-$K2)/5*(N$1-$K$1)+$K2 -> 1203.418 | O2: =($P2-$K2)/5*(O$1-$K$1)+$K2 -> 1210.384 | P2: ='Non-road summary'!J29 -> 1217.35 | Q2: =($U2-$P2)/5*(Q$1-$P$1)+$P2 -> 1228.774 | R2: =($U2-$P2)/5*(R$1-$P$1)+$P2 -> 1240.198 | S2: =($U2-$P2)/5*(S$1-$P$1)+$P2 -> 1251.622 | T2: =($U2-$P2)/5*(T$1-$P$1)+$P2 -> 1263.046 | U2: ='Non-road summary'!K29 -> 1274.47 | V2: =($Z2-$U2)/5*(V$1-$U$1)+$U2 -> 1286.006 | W2: =($Z2-$U2)/5*(W$1-$U$1)+$U2 -> 1297.542 | X2: =($Z2-$U2)/5*(X$1-$U$1)+$U2 -> 1309.078 | Y2: =($Z2-$U2)/5*(Y$1-$U$1)+$U2 -> 1320.614 | Z2: ='Non-road summary'!L29 -> 1332.15 | AA2: =($AE2-$Z2)/5*(AA$1-$Z$1)+$Z2 -> 1340.508 | AB2: =($AE2-$Z2)/5*(AB$1-$Z$1)+$Z2 -> 1348.866 | AC2: =($AE2-$Z2)/5*(AC$1-$Z$1)+$Z2 -> 1357.224 | AD2: =($AE2-$Z2)/5*(AD$1-$Z$1)+$Z2 -> 1365.582 | AE2: ='Non-road summary'!M29 -> 1373.94 | AF2: =($AJ2-$AE2)/5*(AF$1-$AE$1)+$AE2 -> 1379.218 | AG2: =($AJ2-$AE2)/5*(AG$1-$AE$1)+$AE2 -> 1384.496 | AH2: =($AJ2-$AE2)/5*(AH$1-$AE$1)+$AE2 -> 1389.774 | AI2: =($AJ2-$AE2)/5*(AI$1-$AE$1)+$AE2 -> 1395.052 | AJ2: ='Non-road summary'!N29 -> 1400.33
A3: BAU | B3: off-road | C3: TTW | D3: bc | E3: kt | F3: ='Non-road summary'!H39 -> 348.57 | G3: =($K3-$F3)/5*(G$1-$F$1)+$F3 -> 344.352 | H3: =($K3-$F3)/5*(H$1-$F$1)+$F3 -> 340.134 | I3: =($K3-$F3)/5*(I$1-$F$1)+$F3 -> 335.916 | J3: =($K3-$F3)/5*(J$1-$F$1)+$F3 -> 331.698 | K3: ='Non-road summary'!I39 -> 327.48 | L3: =($P3-$K3)/5*(L$1-$K$1)+$K3 -> 324.924 | M3: =($P3-$K3)/5*(M$1-$K$1)+$K3 -> 322.368 | N3: =($P3-$K3)/5*(N$1-$K$1)+$K3 -> 319.812 | O3: =($P3-$K3)/5*(O$1-$K$1)+$K3 -> 317.256 | P3: ='Non-road summary'!J39 -> 314.7 | Q3: =($U3-$P3)/5*(Q$1-$P$1)+$P3 -> 316.138 | R3: =($U3-$P3)/5*(R$1-$P$1)+$P3 -> 317.576 | S3: =($U3-$P3)/5*(S$1-$P$1)+$P3 -> 319.014 | T3: =($U3-$P3)/5*(T$1-$P$1)+$P3 -> 320.452 | U3: ='Non-road summary'!K39 -> 321.89 | V3: =($Z3-$U3)/5*(V$1-$U$1)+$U3 -> 323.288 | W3: =($Z3-$U3)/5*(W$1-$U$1)+$U3 -> 324.686 | X3: =($Z3-$U3)/5*(X$1-$U$1)+$U3 -> 326.084 | Y3: =($Z3-$U3)/5*(Y$1-$U$1)+$U3 -> 327.482 | Z3: ='Non-road summary'!L39 -> 328.88 | AA3: =($AE3-$Z3)/5*(AA$1-$Z$1)+$Z3 -> 328.648 | AB3: =($AE3-$Z3)/5*(AB$1-$Z$1)+$Z3 -> 328.416 | AC3: =($AE3-$Z3)/5*(AC$1-$Z$1)+$Z3 -> 328.184 | AD3: =($AE3-$Z3)/5*(AD$1-$Z$1)+$Z3 -> 327.952 | AE3: ='Non-road summary'!M39 -> 327.72 | AF3: =($AJ3-$AE3)/5*(AF$1-$AE$1)+$AE3 -> 326.35 | AG3: =($AJ3-$AE3)/5*(AG$1-$AE$1)+$AE3 -> 324.98 | AH3: =($AJ3-$AE3)/5*(AH$1-$AE$1)+$AE3 -> 323.61 | AI3: =($AJ3-$AE3)/5*(AI$1-$AE$1)+$AE3 -> 322.24 | AJ3: ='Non-road summary'!N39 -> 320.87
A4: BAU | B4: off-road | C4: TTW | D4: ch4 | E4: kt | F4: ='Non-road summary'!H49 -> 61.95 | G4: =($K4-$F4)/5*(G$1-$F$1)+$F4 -> 62.22 | H4: =($K4-$F4)/5*(H$1-$F$1)+$F4 -> 62.49 | I4: =($K4-$F4)/5*(I$1-$F$1)+$F4 -> 62.76 | J4: =($K4-$F4)/5*(J$1-$F$1)+$F4 -> 63.03 | K4: ='Non-road summary'!I49 -> 63.3 | L4: =($P4-$K4)/5*(L$1-$K$1)+$K4 -> 63.432 | M4: =($P4-$K4)/5*(M$1-$K$1)+$K4 -> 63.564 | N4: =($P4-$K4)/5*(N$1-$K$1)+$K4 -> 63.696 | O4: =($P4-$K4)/5*(O$1-$K$1)+$K4 -> 63.828 | P4: ='Non-road summary'!J49 -> 63.96 | Q4: =($U4-$P4)/5*(Q$1-$P$1)+$P4 -> 64.266 | R4: =($U4-$P4)/5*(R$1-$P$1)+$P4 -> 64.572 | S4: =($U4-$P4)/5*(S$1-$P$1)+$P4 -> 64.878 | T4: =($U4-$P4)/5*(T$1-$P$1)+$P4 -> 65.184 | U4: ='Non-road summary'!K49 -> 65.49 | V4: =($Z4-$U4)/5*(V$1-$U$1)+$U4 -> 65.72 | W4: =($Z4-$U4)/5*(W$1-$U$1)+$U4 -> 65.95 | X4: =($Z4-$U4)/5*(X$1-$U$1)+$U4 -> 66.18 | Y4: =($Z4-$U4)/5*(Y$1-$U$1)+$U4 -> 66.41 | Z4: ='Non-road summary'!L49 -> 66.64 | AA4: =($AE4-$Z4)/5*(AA$1-$Z$1)+$Z4 -> 66.562 | AB4: =($AE4-$Z4)/5*(AB$1-$Z$1)+$Z4 -> 66.484 | AC4: =($AE4-$Z4)/5*(AC$1-$Z$1)+$Z4 -> 66.406 | AD4: =($AE4-$Z4)/5*(AD$1-$Z$1)+$Z4 -> 66.328 | AE4: ='Non-road summary'!M49 -> 66.25 | AF4: =($AJ4-$AE4)/5*(AF$1-$AE$1)+$AE4 -> 65.93 | AG4: =($AJ4-$AE4)/5*(AG$1-$AE$1)+$AE4 -> 65.61 | AH4: =($AJ4-$AE4)/5*(AH$1-$AE$1)+$AE4 -> 65.29 | AI4: =($AJ4-$AE4)/5*(AI$1-$AE$1)+$AE4 -> 64.97 | AJ4: ='Non-road summary'!N49 -> 64.65
A5: Striving | B5: off-road | C5: TTW | D5: co2 | E5: Mt | F5: =H27 -> 1135.46 | G5: =($U5-$F5)/15*(G$1-$F$1)+$F5 -> 1118.5939 | H5: =($U5-$F5)/15*(H$1-$F$1)+$F5 -> 1101.7279 | I5: =($U5-$F5)/15*(I$1-$F$1)+$F5 -> 1084.8618 | J5: =($U5-$F5)/15*(J$1-$F$1)+$F5 -> 1067.9957 | K5: =($U5-$F5)/15*(K$1-$F$1)+$F5 -> 1051.1297 | L5: =($U5-$F5)/15*(L$1-$F$1)+$F5 -> 1034.2636 | M5: =($U5-$F5)/15*(M$1-$F$1)+$F5 -> 1017.3975 | N5: =($U5-$F5)/15*(N$1-$F$1)+$F5 -> 1000.5315 | ... T5: =($U5-$F5)/15*(T$1-$F$1)+$F5 -> 899.33507 | U5: =K27 -> 882.469 | V5: =($AJ5-$U5)/15*(V$1-$U$1)+$U5 -> 848.22857 | W5: =($AJ5-$U5)/15*(W$1-$U$1)+$U5 -> 813.98813 | X5: =($AJ5-$U5)/15*(X$1-$U$1)+$U5 -> 779.7477 | Y5: =($AJ5-$U5)/15*(Y$1-$U$1)+$U5 -> 745.50727 | Z5: =($AJ5-$U5)/15*(Z$1-$U$1)+$U5 -> 711.26683 | AA5: =($AJ5-$U5)/15*(AA$1-$U$1)+$U5 -> 677.0264 | AB5: =($AJ5-$U5)/15*(AB$1-$U$1)+$U5 -> 642.78597 | AC5: =($AJ5-$U5)/15*(AC$1-$U$1)+$U5 -> 608.54553 | ... AI5: =($AJ5-$U5)/15*(AI$1-$U$1)+$U5 -> 403.10293 | AJ5: =N27 -> 368.8625
A6: Striving | B6: off-road | C6: TTW | D6: bc | E6: kt | F6: 252.12 | G6: =($U6-$F6)/15*(G$1-$F$1)+$F6 -> 247.11547 | H6: =($U6-$F6)/15*(H$1-$F$1)+$F6 -> 242.11093 | I6: =($U6-$F6)/15*(I$1-$F$1)+$F6 -> 237.1064 | J6: =($U6-$F6)/15*(J$1-$F$1)+$F6 -> 232.10187 | K6: =($U6-$F6)/15*(K$1-$F$1)+$F6 -> 227.09733 | L6: =($U6-$F6)/15*(L$1-$F$1)+$F6 -> 222.0928 | M6: =($U6-$F6)/15*(M$1-$F$1)+$F6 -> 217.08827 | N6: =($U6-$F6)/15*(N$1-$F$1)+$F6 -> 212.08373 | ... T6: =($U6-$F6)/15*(T$1-$F$1)+$F6 -> 182.05653 | U6: =K37 -> 177.052 | V6: =($AJ6-$U6)/15*(V$1-$U$1)+$U6 -> 169.55853 | W6: =($AJ6-$U6)/15*(W$1-$U$1)+$U6 -> 162.06507 | X6: =($AJ6-$U6)/15*(X$1-$U$1)+$U6 -> 154.5716 | Y6: =($AJ6-$U6)/15*(Y$1-$U$1)+$U6 -> 147.07813 | Z6: =($AJ6-$U6)/15*(Z$1-$U$1)+$U6 -> 139.58467 | AA6: =($AJ6-$U6)/15*(AA$1-$U$1)+$U6 -> 132.0912 | AB6: =($AJ6-$U6)/15*(AB$1-$U$1)+$U6 -> 124.59773 | AC6: =($AJ6-$U6)/15*(AC$1-$U$1)+$U6 -> 117.10427 | ... AI6: =($AJ6-$U6)/15*(AI$1-$U$1)+$U6 -> 72.143467 | AJ6: =N47 -> 64.65
A7: Striving | B7: off-road | C7: TTW | D7: ch4 | E7: kt | F7: 33.49 | G7: =($U7-$F7)/15*(G$1-$F$1)+$F7 -> 33.196 | H7: =($U7-$F7)/15*(H$1-$F$1)+$F7 -> 32.902 | I7: =($U7-$F7)/15*(I$1-$F$1)+$F7 -> 32.608 | J7: =($U7-$F7)/15*(J$1-$F$1)+$F7 -> 32.314 | K7: =($U7-$F7)/15*(K$1-$F$1)+$F7 -> 32.02 | L7: =($U7-$F7)/15*(L$1-$F$1)+$F7 -> 31.726 | M7: =($U7-$F7)/15*(M$1-$F$1)+$F7 -> 31.432 | N7: =($U7-$F7)/15*(N$1-$F$1)+$F7 -> 31.138 | ... T7: =($U7-$F7)/15*(T$1-$F$1)+$F7 -> 29.374 | U7: 29.08 | V7: =($AJ7-$U7)/15*(V$1-$U$1)+$U7 -> 28.830667 | W7: =($AJ7-$U7)/15*(W$1-$U$1)+$U7 -> 28.581333 | X7: =($AJ7-$U7)/15*(X$1-$U$1)+$U7 -> 28.332 | Y7: =($AJ7-$U7)/15*(Y$1-$U$1)+$U7 -> 28.082667 | Z7: =($AJ7-$U7)/15*(Z$1-$U$1)+$U7 -> 27.833333 | AA7: =($AJ7-$U7)/15*(AA$1-$U$1)+$U7 -> 27.584 | AB7: =($AJ7-$U7)/15*(AB$1-$U$1)+$U7 -> 27.334667 | AC7: =($AJ7-$U7)/15*(AC$1-$U$1)+$U7 -> 27.085333 | ... AI7: =($AJ7-$U7)/15*(AI$1-$U$1)+$U7 -> 25.589333 | AJ7: 25.34
A20: CO2 emissions from non-road transport (Mt CO2)
H21: 2020 | I21: 2025 | J21: 2030 | K21: 2035 | L21: 2040 | M21: 2045 | N21: 2050 | P21: Sub-sector | Q21: 2035 | R21: 2050
A22: TRA_OT_CNS | H22: 259.09 | K22: ='Non-road summary'!K24*(1-Q22) -> 164.082 | N22: ='Non-road summary'!N24*(1-R22) -> 0 | P22: TRA_OT_CNS | Q22: 0.4 | R22: 1
A23: TRA_OT_AGR | H23: 244.1 | K23: ='Non-road summary'!K25*(1-Q23) -> 142.044 | N23: ='Non-road summary'!N25*(1-R23) -> 0 | P23: TRA_OT_AGR | Q23: 0.4 | R23: 1
A24: TRA_OT_RAI | H24: 82.05 | K24: ='Non-road summary'!K26*(1-Q24) -> 42.24 | N24: ='Non-road summary'!N26*(1-R24) -> 0 | P24: TRA_OT_RAI | Q24: 0.4 | R24: 1
A25: TRA_OT_SHIP_NAT | H25: 169.28 | K25: ='Non-road summary'!K27*(1-Q25) -> 147.063 | N25: ='Non-road summary'!N27*(1-R25) -> 53.2775 | P25: TRA_OT_SHIP_NAT | Q25: 0.3 | R25: 0.75
A26: TRA_OT_OTHER | H26: 380.94 | K26: ='Non-road summary'!K28*(1-Q26) -> 387.04 | N26: ='Non-road summary'!N28*(1-R26) -> 315.585 | P26: TRA_OT_OTHER | Q26: 0.2 | R26: 0.5
A27: SUM | H27: =SUM(H22:H26) -> 1135.46 | K27: =SUM(K22:K26) -> 882.469 | N27: =SUM(N22:N26) -> 368.8625
A28: ALL SUM
A30: BC emissions from non-road transport (kt PM) | Q30: % CO2 reduction | S30: % BC reduction
H31: 2020 | K31: 2035 | N31: 2050 | P31: Sub-sector | Q31: 2035 | R31: 2050 | S31: 2035 | T31: 2050
A32: TRA_OT_CNS | H32: 115.69 | K32: ='Non-road summary'!K34*(1-S32) -> 39.96 | N32: ='Non-road summary'!N34*(1-T32) -> 0 | P32: TRA_OT_CNS | Q32: 0.4 | R32: 1 | S32: 0.6 | T32: 1
A33: TRA_OT_AGR | H33: 104.56 | K33: ='Non-road summary'!K35*(1-S33) -> 33.608 | N33: ='Non-road summary'!N35*(1-T33) -> 0 | P33: TRA_OT_AGR | Q33: 0.4 | R33: 1 | S33: 0.6 | T33: 1
A34: TRA_OT_RAI | H34: 35.66 | K34: ='Non-road summary'!K36*(1-S34) -> 24.415 | N34: ='Non-road summary'!N36*(1-T34) -> 0 | P34: TRA_OT_RAI | Q34: 0.4 | R34: 1 | S34: 0.05 | T34: 1
A35: TRA_OT_SHIP_NAT | H35: 85.66 | K35: ='Non-road summary'!K37*(1-S35) -> 74.893 | N35: ='Non-road summary'!N37*(1-T35) -> 27.5775 | P35: TRA_OT_SHIP_NAT | Q35: 0.3 | R35: 0.75 | S35: 0.3 | T35: 0.75
A36: TRA_OT_OTHER | H36: 6.99 | K36: ='Non-road summary'!K38*(1-S36) -> 4.176 | N36: ='Non-road summary'!N38*(1-T36) -> 2.465 | P36: TRA_OT_OTHER | Q36: 0.2 | R36: 0.5 | S36: 0.2 | T36: 0.5
A37: SUM | H37: =SUM(H32:H36) -> 348.56 | K37: =SUM(K32:K36) -> 177.052 | N37: =SUM(N32:N36) -> 30.0425
A38: ALL SUM | H38: 348.57 | K38: 321.88 | N38: 320.86
A40: CH4 emissions from non-road transport (kt CH4)
H41: 2020 | K41: 2035 | N41: 2050
A42: TRA_OT_CNS | H42: 15.11 | K42: 16.27 | N42: 16.88
A43: TRA_OT_AGR | H43: 14.3 | K43: 14.08 | N43: 13.3
A44: TRA_OT_RAI | H44: 4.74 | K44: 4.2 | N44: 3.31
A45: TRA_OT_SHIP_NAT | H45: 16.34 | K45: 20.33 | N45: 20.62
A46: TRA_OT_OTHER | H46: 11.44 | K46: 10.6 | N46: 10.56
A47: SUM | H47: 61.95 | K47: 65.49 | N47: 64.65
A48: ALL SUM | H48: 61.92 | K48: 65.49 | N48: 64.68

Sheet Agg2
A1: Sector | B1: Sub-Sector | C1: Species | D1: Unit | E1: 1990 | F1: 1995 | G1: 2000 | H1: 2005 | I1: 2010 | J1: 2015 | K1: 2020 | L1: 2025 | M1: 2030 | N1: 2035 | O1: 2040 | P1: 2045 | Q1: 2050
A2: off-road | B2: TRA_OT_CNS | C2: co2 | D2: Mt | E2: 122 | F2: 100.99 | G2: 110.09 | H2: 116 | I2: 119.42 | J2: 135.7 | K2: 259.09 | L2: 264.83 | M2: 258.71 | N2: 273.47 | O2: 287.07 | P2: 284.86 | Q2: 279.65
A3: off-road | B3: TRA_OT_AGR | C3: co2 | D3: Mt | E3: 218.22 | F3: 227.75 | G3: 201.59 | H3: 227.26 | I3: 227.06 | J3: 222.61 | K3: 244.1 | L3: 245.81 | M3: 241.81 | N3: 236.74 | O3: 232.24 | P3: 229.91 | Q3: 221.23
A4: off-road | B4: TRA_OT_RAI | C4: co2 | D4: Mt | E4: 92.03 | F4: 74.01 | G4: 82.09 | H4: 98.26 | I4: 82.94 | J4: 90.4 | K4: 82.05 | L4: 77.59 | M4: 73.8 | N4: 70.4 | O4: 66.31 | P4: 61.24 | Q4: 55.17
A5: off-road | B5: TRA_OT_SHIP_NAT | C5: co2 | D5: Mt | E5: 74.87 | F5: 61.53 | G5: 129.96 | H5: 140.41 | I5: 146.93 | J5: 180.01 | K5: 169.28 | L5: 185.68 | M5: 199.43 | N5: 210.09 | O5: 216.53 | P5: 218.22 | Q5: 213.11
A6: off-road | B6: TRA_OT_OTHER | C6: co2 | D6: Mt | E6: 311.24 | F6: 284.69 | G6: 309.03 | H6: 327.79 | I6: 332.55 | J6: 378.04 | K6: 380.94 | L6: 408.63 | M6: 443.57 | N6: 483.8 | O6: 530 | P6: 579.66 | Q6: 631.17
A7: off-road | B7: TRA_OT_CNS | C7: bc | D7: kt | E7: 98.19 | F7: 82.21 | G7: 88.79 | H7: 86.46 | I7: 84.62 | J7: 82.66 | K7: 115.69 | L7: 103.7 | M7: 93.89 | N7: 99.9 | O7: 105.81 | P7: 105.41 | Q7: 104.79
A8: off-road | B8: TRA_OT_AGR | C8: bc | D8: kt | E8: 148.32 | F8: 156.19 | G8: 140.44 | H8: 148.52 | I8: 140.75 | J8: 124.82 | K8: 104.56 | L8: 93.27 | M8: 86.95 | N8: 84.02 | O8: 81.85 | P8: 80.22 | Q8: 77.93
A9: off-road | B9: TRA_OT_RAI | C9: bc | D9: kt | E9: 54.66 | F9: 44.03 | G9: 48.81 | H9: 56.54 | I9: 46.19 | J9: 44.49 | K9: 35.66 | L9: 30.29 | M9: 27.55 | N9: 25.7 | O9: 25.31 | P9: 24.5 | Q9: 22.9
A10: off-road | B10: TRA_OT_SHIP_NAT | C10: bc | D10: kt | E10: 27.88 | F10: 23.29 | G10: 67.73 | H10: 72.71 | I10: 76.66 | J10: 94.26 | K10: 85.66 | L10: 93.98 | M10: 100.64 | N10: 106.99 | O10: 110.91 | P10: 112.66 | Q10: 110.31
A11: off-road | B11: TRA_OT_OTHER | C11: bc | D11: kt | E11: 16.97 | F11: 7.55 | G11: 5.93 | H11: 8.47 | I11: 8.88 | J11: 8.91 | K11: 6.99 | L11: 6.22 | M11: 5.62 | N11: 5.22 | O11: 5.02 | P11: 4.92 | Q11: 4.93
A12: off-road | B12: TRA_OT_CNS | C12: ch4 | D12: kt | E12: 6.91 | F12: 5.7 | G12: 6.24 | H12: 6.57 | I12: 6.86 | J12: 7.88 | K12: 15.11 | L12: 15.5 | M12: 15.34 | N12: 16.27 | O12: 17.22 | P12: 17.14 | Q12: 16.88
... A16: off-road | B16: TRA_OT_OTHER | C16: ch4 | D16: kt | E16: 12.18 | F16: 8.97 | G16: 7.57 | H16: 7.87 | I16: 8.66 | J16: 9.37 | K16: 11.44 | L16: 10.8 | M16: 10.6 | N16: 10.6 | O16: 10.64 | P16: 10.56 | Q16: 10.56

Sheet Non-road CO2_CLEAN
A1: Region | B1: Sector | C1: 1990 | D1: 1995 | E1: 2000 | F1: 2005 | G1: 2010 | H1: 2015 | I1: 2020 | J1: 2025 | K1: 2030 | L1: 2035 | M1: 2040 | N1: 2045 | O1: 2050
A2: AFRI_EAST | B2: TRA_OTH
A3: AFRI_EAST | B3: TRA_OT_CNS | C3: 0.36 | D3: 0.51 | E3: 0.57 | F3: 0.71 | G3: 0.83 | H3: 1.75 | I3: 2.42 | J3: 2.72 | K3: 3.17 | L3: 3.74 | M3: 4.42 | N3: 5.14 | O3: 5.89
A4: AFRI_EAST | B4: TRA_OT_AGR | C4: 0.28 | D4: 0.38 | E4: 0.59 | F4: 0.8 | G4: 0.51 | H4: 0.63 | I4: 0.2 | J4: 0.21 | K4: 0.21 | L4: 0.22 | M4: 0.22 | N4: 0.21 | O4: 0.21
A5: AFRI_EAST | B5: TRA_OT_RAI | C5: 0.13 | D5: 0.08 | E5: 0.08 | F5: 0.1 | G5: 0.08 | H5: 0.2 | I5: 0.26 | J5: 0.3 | K5: 0.36 | L5: 0.43 | M5: 0.51 | N5: 0.61 | O5: 0.71
A6: AFRI_EAST | B6: TRA_OT_SHIP_NAT
A7: AFRI_EAST | B7: TRA_OT_OTHER | C7: 0.81 | D7: 1.05 | E7: 1.13 | F7: 2.04 | G7: 2.27 | H7: 2.73 | I7: 0.88 | J7: 1.03 | K7: 1.24 | L7: 1.5 | M7: 1.79 | N7: 2.12 | O7: 2.47
A8: AFRI_EAST | B8: SUM | C8: 1.58 | D8: 2.02 | E8: 2.38 | F8: 3.65 | G8: 3.7 | H8: 5.31 | I8: 3.75 | J8: 4.25 | K8: 4.98 | L8: 5.88 | M8: 6.94 | N8: 8.08 | O8: 9.29
A9: AFRI_NORT | B9: TRA_OTH
A10: AFRI_NORT | B10: TRA_OT_CNS | C10: 3.27 | D10: 2.69 | E10: 4.75 | F10: 4.18 | G10: 4.81 | H10: 5.54 | I10: 7.49 | J10: 6.43 | K10: 4.87 | L10: 4.93 | M10: 5.07 | N10: 4.82 | O10: 4.56
A11: AFRI_NORT | B11: TRA_OT_AGR | C11: 1.13 | D11: 1.57 | E11: 1.95 | F11: 6.55 | G11: 7.67 | H11: 4.64 | I11: 5.99 | J11: 6.93 | K11: 7.74 | L11: 8.28 | M11: 8.94 | N11: 9.6 | O11: 10.25
A12: AFRI_NORT | B12: TRA_OT_RAI | C12: 0.03 | E12: 0.04 | F12: 0.04 | G12: 0.27 | H12: 0.13 | I12: 0.42 | J12: 0.41 | K12: 0.4 | L12: 0.4 | M12: 0.39 | N12: 0.39 | O12: 0.39
A13: AFRI_NORT | B13: TRA_OT_SHIP_NAT | C13: 0.97 | D13: 1.21 | E13: 2.42 | F13: 1.43 | G13: 1.69 | H13: 0.8 | I13: 0.88 | J13: 1.06 | K13: 1.22 | L13: 1.32 | M13: 1.39 | N13: 1.4
A14: AFRI_NORT | B14: TRA_OT_OTHER | C14: 0.62 | D14: 1.31 | E14: 1.37 | F14: 1.47 | G14: 1.71 | H14: 1.35 | I14: 2.39 | J14: 2.73 | K14: 3 | L14: 3.26 | M14: 3.5 | N14: 3.68 | O14: 3.84
A15: AFRI_NORT | B15: SUM | C15: 6.02 | D15: 6.78 | E15: 10.53 | F15: 13.66 | G15: 16.15 | H15: 12.46 | I15: 17.17 | J15: 17.56 | K15: 17.24 | L15: 18.19 | M15: 19.29 | N15: 19.89 | O15: 19.04
A16: AFRI_WEST | B16: TRA_OTH
A17: AFRI_WEST | B17: TRA_OT_CNS | C17: 0.51 | D17: 0.73 | E17: 0.98 | F17: 1.11 | G17: 1.65 | H17: 2.47 | I17: 4.03 | J17: 4.95 | K17: 5.76 | L17: 6.81 | M17: 8.04 | N17: 9.35 | O17: 10.73
A18: AFRI_WEST | B18: TRA_OT_AGR | C18: 0.54 | D18: 0.73 | E18: 1.14 | F18: 0.89 | G18: 1.25 | H18: 2 | I18: 0.63 | J18: 0.65 | K18: 0.67 | L18: 0.68 | M18: 0.68 | N18: 0.67 | O18: 0.66
A19: AFRI_WEST | B19: TRA_OT_RAI | C19: 0.56 | D19: 0.34 | E19: 0.47 | F19: 0.42 | G19: 0.41 | H19: 0.9 | I19: 1.13 | J19: 1.31 | K19: 1.58 | L19: 1.9 | M19: 2.27 | N19: 2.69 | O19: 3.15
A20: AFRI_WEST | B20: TRA_OT_SHIP_NAT | E20: 0.52 | F20: 0.54 | G20: 0.64 | H20: 1.39 | I20: 1.49 | J20: 1.57 | K20: 1.73 | L20: 1.92 | M20: 2.1 | N20: 2.28 | O20: 2.43
A21: AFRI_WEST | B21: TRA_OT_OTHER | C21: 1.31 | D21: 1.7 | E21: 3.28 | F21: 4.99 | G21: 2.61 | H21: 2.88 | I21: 0.93 | J21: 1.09 | K21: 1.32 | L21: 1.59 | M21: 1.9 | N21: 2.24 | O21: 2.61
A22: AFRI_WEST | B22: SUM | C22: 2.92 | D22: 3.5 | E22: 6.39 | F22: 7.94 | G22: 6.56 | H22: 9.65 | I22: 8.21 | J22: 9.58 | K22: 11.06 | L22: 12.89 | M22: 15 | N22: 17.24 | O22: 19.58
A23: ASIA_STAN | B23: TRA_OTH
A24: ASIA_STAN | B24: TRA_OT_CNS | C24: 4.3 | D24: 2.96 | E24: 1.4 | F24: 1.54 | G24: 0.6 | H24: 2.4 | I24: 1.86 | J24: 1.95 | K24: 2.13 | L24: 2.22 | M24: 2.39 | N24: 2.35 | O24: 2.28
A25: ASIA_STAN | B25: TRA_OT_AGR | C25: 2.59 | D25: 1.8 | E25: 1.36 | F25: 1.5 | G25: 1.14 | H25: 1.3 | I25: 0.83 | J25: 0.95 | K25: 1.05 | L25: 1.01 | M25: 0.96 | N25: 0.91 | O25: 0.84
A26: ASIA_STAN | B26: TRA_OT_RAI | C26: 1.41 | D26: 0.98 | E26: 0.86 | F26: 0.95 | G26: 0.6 | H26: 0.27 | I26: 0.43 | J26: 0.46 | K26: 0.5 | L26: 0.53 | M26: 0.55 | N26: 0.55 | O26: 0.53
A27: ASIA_STAN | B27: TRA_OT_SHIP_NAT | G27: 0.06 | H27: 0.91
A28: ASIA_STAN | B28: TRA_OT_OTHER | C28: 0.26 | D28: 0.5 | E28: 0.65 | F28: 0.41 | G28: 0.85 | H28: 0.37 | I28: 1.14 | J28: 1.29 | K28: 1.43 | L28: 1.57 | M28: 1.69 | N28: 1.78 | O28: 1.84
A29: ASIA_STAN | B29: SUM | C29: 8.55 | D29: 6.23 | E29: 4.27 | F29: 4.4 | G29: 3.25 | H29: 5.25 | I29: 4.26 | J29: 4.65 | K29: 5.11 | L29: 5.34 | M29: 5.6 | N29: 5.6 | O29: 5.48
A30: BRAZ_WHOL | B30: TRA_OTH
A31: BRAZ_WHOL | B31: TRA_OT_CNS | C31: 0.3 | D31: 0.45 | E31: 0.47 | F31: 0.5 | G31: 0.58 | H31: 0.79 | I31: 0.57 | J31: 0.53 | K31: 0.46 | L31: 0.5 | M31: 0.55 | N31: 0.54 | O31: 0.53
A32: BRAZ_WHOL | B32: TRA_OT_AGR | C32: 7.98 | D32: 10.51 | E32: 10.95 | F32: 11.71 | G32: 13.2 | H32: 14.31 | I32: 15.08 | J32: 15.58 | K32: 16.33 | L32: 16.76 | M32: 16.84 | N32: 16.33 | O32: 15.52
A33: BRAZ_WHOL | B33: TRA_OT_RAI | C33: 1.61 | D33: 1.35 | E33: 1.24 | F33: 1.74 | G33: 2.63 | H33: 2.75 | I33: 2.69 | J33: 2.7 | K33: 2.88 | L33: 3.07 | M33: 3.18 | N33: 3.19 | O33: 3.07
A34: BRAZ_WHOL | B34: TRA_OT_SHIP_NAT | E34: 2.93 | F34: 3.6 | G34: 4.28 | H34: 3.01 | I34: 2.18 | J34: 2.01 | K34: 1.76 | L34: 1.46 | M34: 1.12 | N34: 0.8 | O34: 0.49
A35: BRAZ_WHOL | B35: TRA_OT_OTHER | C35: 5.65 | D35: 7 | E35: 9.14 | F35: 7.45 | G35: 10.43 | H35: 12.24 | I35: 9.78 | J35: 10.48 | K35: 11.74 | L35: 13.42 | M35: 15.27 | N35: 17.48 | O35: 19.43
A36: BRAZ_WHOL | B36: SUM | C36: 15.54 | D36: 19.31 | E36: 24.73 | F36: 25.01 | G36: 31.11 | H36: 33.09 | I36: 30.3 | J36: 31.3 | K36: 33.17 | L36: 35.21 | M36: 36.96 | N36: 38.34 | O36: 39.03
A37: CANA_WHOL | B37: TRA_OTH
A38: CANA_WHOL | B38: TRA_OT_CNS | C38: 3.15 | D38: 3.24 | E38: 4.17 | F38: 2.99 | G38: 3.58 | H38: 3.69 | I38: 12.73 | J38: 11.6 | K38: 10.67 | L38: 10.18 | M38: 9.86 | N38: 9.45 | O38: 9.05
A39: CANA_WHOL | B39: TRA_OT_AGR | C39: 4.58 | D39: 5.71 | E39: 6.47 | F39: 5.94 | G39: 6.06 | H39: 7.31 | I39: 14.87 | J39: 14.63 | K39: 14.44 | L39: 11.99 | M39: 11.72 | N39: 11.36 | O39: 10.89
A40: CANA_WHOL | B40: TRA_OT_RAI | C40: 6.22 | D40: 5.63 | E40: 5.78 | F40: 5.92 | G40: 5.86 | H40: 6.6 | I40: 5.58 | J40: 5.4 | K40: 5.29 | L40: 5.2 | M40: 5.13 | N40: 5.07 | O40: 5.02
...

Sheet Non-road CO2
A1: CO2 emissions from non-road transport
A3: Pollutant: CO2
A4: Scenario: ECLIPSE_V6b_CLE_base
A5: Region: All EMF Regions
A6: UserID: jm110
A7: Unit: Mt CO2
A10: Region | B10: [kt/yr] | C10: 1990 | D10: 1995 | E10: 2000 | F10: 2005 | G10: 2010 | H10: 2015 | I10: 2020 | J10: 2025 | K10: 2030 | L10: 2035 | M10: 2040 | N10: 2045 | O10: 2050
A11: AFRI_EAST | B11: TRA_OTH
A12: AFRI_EAST | B12: TRA_OT_CNS | C12: 0.36 | D12: 0.51 | E12: 0.57 | F12: 0.71 | G12: 0.83 | H12: 1.75 | I12: 2.42 | J12: 2.72 | K12: 3.17 | L12: 3.74 | M12: 4.42 | N12: 5.14 | O12: 5.89
A13: AFRI_EAST | B13: TRA_OT_AGR | C13: 0.28 | D13: 0.38 | E13: 0.59 | F13: 0.8 | G13: 0.51 | H13: 0.63 | I13: 0.2 | J13: 0.21 | K13: 0.21 | L13: 0.22 | M13: 0.22 | N13: 0.21 | O13: 0.21
A14: AFRI_EAST | B14: TRA_OT_RAI | C14: 0.13 | D14: 0.08 | E14: 0.08 | F14: 0.1 | G14: 0.08 | H14: 0.2 | I14: 0.26 | J14: 0.3 | K14: 0.36 | L14: 0.43 | M14: 0.51 | N14: 0.61 | O14: 0.71
A15: AFRI_EAST | B15: TRA_OT_SHIP_NAT
A16: AFRI_EAST | B16: TRA_OT_OTHER | C16: 0.81 | D16: 1.05 | E16: 1.13 | F16: 2.04 | G16: 2.27 | H16: 2.73 | I16: 0.88 | J16: 1.03 | K16: 1.24 | L16: 1.5 | M16: 1.79 | N16: 2.12 | O16: 2.47
A17: AFRI_EAST | B17: SUM | C17: 1.58 | D17: 2.02 | E17: 2.38 | F17: 3.65 | G17: 3.7 | H17: 5.31 | I17: 3.75 | J17: 4.25 | K17: 4.98 | L17: 5.88 | M17: 6.94 | N17: 8.08 | O17: 9.29
A18: AFRI_NORT | B18: TRA_OTH
A19: AFRI_NORT | B19: TRA_OT_CNS | C19: 3.27 | D19: 2.69 | E19: 4.75 | F19: 4.18 | G19: 4.81 | H19: 5.54 | I19: 7.49 | J19: 6.43 | K19: 4.87 | L19: 4.93 | M19: 5.07 | N19: 4.82 | O19: 4.56
A20: AFRI_NORT | B20: TRA_OT_AGR | C20: 1.13 | D20: 1.57 | E20: 1.95 | F20: 6.55 | G20: 7.67 | H20: 4.64 | I20: 5.99 | J20: 6.93 | K20: 7.74 | L20: 8.28 | M20: 8.94 | N20: 9.6 | O20: 10.25
A21: AFRI_NORT | B21: TRA_OT_RAI | C21: 0.03 | E21: 0.04 | F21: 0.04 | G21: 0.27 | H21: 0.13 | I21: 0.42 | J21: 0.41 | K21: 0.4 | L21: 0.4 | M21: 0.39 | N21: 0.39 | O21: 0.39
A22: AFRI_NORT | B22: TRA_OT_SHIP_NAT | C22: 0.97 | D22: 1.21 | E22: 2.42 | F22: 1.43 | G22: 1.69 | H22: 0.8 | I22: 0.88 | J22: 1.06 | K22: 1.22 | L22: 1.32 | M22: 1.39 | N22: 1.4
A23: AFRI_NORT | B23: TRA_OT_OTHER | C23: 0.62 | D23: 1.31 | E23: 1.37 | F23: 1.47 | G23: 1.71 | H23: 1.35 | I23: 2.39 | J23: 2.73 | K23: 3 | L23: 3.26 | M23: 3.5 | N23: 3.68 | O23: 3.84
A24: AFRI_NORT | B24: SUM | C24: 6.02 | D24: 6.78 | E24: 10.53 | F24: 13.66 | G24: 16.15 | H24: 12.46 | I24: 17.17 | J24: 17.56 | K24: 17.24 | L24: 18.19 | M24: 19.29 | N24: 19.89 | O24: 19.04
A25: AFRI_WEST | B25: TRA_OTH
A26: AFRI_WEST | B26: TRA_OT_CNS | C26: 0.51 | D26: 0.73 | E26: 0.98 | F26: 1.11 | G26: 1.65 | H26: 2.47 | I26: 4.03 | J26: 4.95 | K26: 5.76 | L26: 6.81 | M26: 8.04 | N26: 9.35 | O26: 10.73
A27: AFRI_WEST | B27: TRA_OT_AGR | C27: 0.54 | D27: 0.73 | E27: 1.14 | F27: 0.89 | G27: 1.25 | H27: 2 | I27: 0.63 | J27: 0.65 | K27: 0.67 | L27: 0.68 | M27: 0.68 | N27: 0.67 | O27: 0.66
A28: AFRI_WEST | B28: TRA_OT_RAI | C28: 0.56 | D28: 0.34 | E28: 0.47 | F28: 0.42 | G28: 0.41 | H28: 0.9 | I28: 1.13 | J28: 1.31 | K28: 1.58 | L28: 1.9 | M28: 2.27 | N28: 2.69 | O28: 3.15
A29: AFRI_WEST | B29: TRA_OT_SHIP_NAT | E29: 0.52 | F29: 0.54 | G29: 0.64 | H29: 1.39 | I29: 1.49 | J29: 1.57 | K29: 1.73 | L29: 1.92 | M29: 2.1 | N29: 2.28 | O29: 2.43
A30: AFRI_WEST | B30: TRA_OT_OTHER | C30: 1.31 | D30: 1.7 | E30: 3.28 | F30: 4.99 | G30: 2.61 | H30: 2.88 | I30: 0.93 | J30: 1.09 | K30: 1.32 | L30: 1.59 | M30: 1.9 | N30: 2.24 | O30: 2.61
A31: AFRI_WEST | B31: SUM | C31: 2.92 | D31: 3.5 | E31: 6.39 | F31: 7.94 | G31: 6.56 | H31: 9.65 | I31: 8.21 | J31: 9.58 | K31: 11.06 | L31: 12.89 | M31: 15 | N31: 17.24 | O31: 19.58
A32: ASIA_STAN | B32: TRA_OTH
A33: ASIA_STAN | B33: TRA_OT_CNS | C33: 4.3 | D33: 2.96 | E33: 1.4 | F33: 1.54 | G33: 0.6 | H33: 2.4 | I33: 1.86 | J33: 1.95 | K33: 2.13 | L33: 2.22 | M33: 2.39 | N33: 2.35 | O33: 2.28
A34: ASIA_STAN | B34: TRA_OT_AGR | C34: 2.59 | D34: 1.8 | E34: 1.36 | F34: 1.5 | G34: 1.14 | H34: 1.3 | I34: 0.83 | J34: 0.95 | K34: 1.05 | L34: 1.01 | M34: 0.96 | N34: 0.91 | O34: 0.84
A35: ASIA_STAN | B35: TRA_OT_RAI | C35: 1.41 | D35: 0.98 | E35: 0.86 | F35: 0.95 | G35: 0.6 | H35: 0.27 | I35: 0.43 | J35: 0.46 | K35: 0.5 | L35: 0.53 | M35: 0.55 | N35: 0.55 | O35: 0.53
A36: ASIA_STAN | B36: TRA_OT_SHIP_NAT | G36: 0.06 | H36: 0.91
A37: ASIA_STAN | B37: TRA_OT_OTHER | C37: 0.26 | D37: 0.5 | E37: 0.65 | F37: 0.41 | G37: 0.85 | H37: 0.37 | I37: 1.14 | J37: 1.29 | K37: 1.43 | L37: 1.57 | M37: 1.69 | N37: 1.78 | O37: 1.84
A38: ASIA_STAN | B38: SUM | C38: 8.55 | D38: 6.23 | E38: 4.27 | F38: 4.4 | G38: 3.25 | H38: 5.25 | I38: 4.26 | J38: 4.65 | K38: 5.11 | L38: 5.34 | M38: 5.6 | N38: 5.6 | O38: 5.48
A39: BRAZ_WHOL | B39: TRA_OTH
A40: BRAZ_WHOL | B40: TRA_OT_CNS | C40: 0.3 | D40: 0.45 | E40: 0.47 | F40: 0.5 | G40: 0.58 | H40: 0.79 | I40: 0.57 | J40: 0.53 | K40: 0.46 | L40: 0.5 | M40: 0.55 | N40: 0.54 | O40: 0.53
A41: BRAZ_WHOL | B41: TRA_OT_AGR | C41: 7.98 | D41: 10.51 | E41: 10.95 | F41: 11.71 | G41: 13.2 | H41: 14.31 | I41: 15.08 | J41: 15.58 | K41: 16.33 | L41: 16.76 | M41: 16.84 | N41: 16.33 | O41: 15.52
A42: BRAZ_WHOL | B42: TRA_OT_RAI | C42: 1.61 | D42: 1.35 | E42: 1.24 | F42: 1.74 | G42: 2.63 | H42: 2.75 | I42: 2.69 | J42: 2.7 | K42: 2.88 | L42: 3.07 | M42: 3.18 | N42: 3.19 | O42: 3.07
A43: BRAZ_WHOL | B43: TRA_OT_SHIP_NAT | E43: 2.93 | F43: 3.6 | G43: 4.28 | H43: 3.01 | I43: 2.18 | J43: 2.01 | K43: 1.76 | L43: 1.46 | M43: 1.12 | N43: 0.8 | O43: 0.49
...

Sheet Non-road BC_CLEAN
A1: Region | B1: Sector | C1: 1990 | D1: 1995 | E1: 2000 | F1: 2005 | G1: 2010 | H1: 2015 | I1: 2020 | J1: 2025 | K1: 2030 | L1: 2035 | M1: 2040 | N1: 2045 | O1: 2050
A2: AFRI_EAST | B2: TRA_OTH
A3: AFRI_EAST | B3: TRA_OT_CNS | C3: 0.29 | D3: 0.42 | E3: 0.47 | F3: 0.58 | G3: 0.68 | H3: 1.43 | I3: 1.98 | J3: 2.23 | K3: 2.6 | L3: 3.07 | M3: 3.63 | N3: 4.22 | O3: 4.84
A4: AFRI_EAST | B4: TRA_OT_AGR | C4: 0.2 | D4: 0.27 | E4: 0.42 | F4: 0.57 | G4: 0.36 | H4: 0.45 | I4: 0.14 | J4: 0.14 | K4: 0.15 | L4: 0.15 | M4: 0.15 | N4: 0.15 | O4: 0.15
A5: AFRI_EAST | B5: TRA_OT_RAI | C5: 0.08 | D5: 0.05 | E5: 0.05 | F5: 0.06 | G5: 0.05 | H5: 0.12 | I5: 0.16 | J5: 0.18 | K5: 0.22 | L5: 0.26 | M5: 0.31 | N5: 0.37 | O5: 0.44
A6: AFRI_EAST | B6: TRA_OT_SHIP_NAT
A7: AFRI_EAST | B7: TRA_OT_OTHER | C7: 0 | D7: 0 | E7: 0 | F7: 0 | G7: 0.01 | H7: 0.01 | I7: 0 | J7: 0 | K7: 0 | L7: 0 | M7: 0 | N7: 0.01 | O7: 0.01
A8: AFRI_EAST | B8: SUM | C8: 0.57 | D8: 0.74 | E8: 0.94 | F8: 1.21 | G8: 1.1 | H8: 2.01 | I8: 2.28 | J8: 2.56 | K8: 2.97 | L8: 3.49 | M8: 4.1 | N8: 4.75 | O8: 5.43
A9: AFRI_NORT | B9: TRA_OTH
A10: AFRI_NORT | B10: TRA_OT_CNS | C10: 2.67 | D10: 2.2 | E10: 3.89 | F10: 3.42 | G10: 3.99 | H10: 4.69 | I10: 6.46 | J10: 5.54 | K10: 4.2 | L10: 4.25 | M10: 4.37 | N10: 4.15 | O10: 3.93
A11: AFRI_NORT | B11: TRA_OT_AGR | C11: 0.79 | D11: 1.11 | E11: 1.37 | F11: 4.6 | G11: 5.46 | H11: 3.38 | I11: 4.44 | J11: 5.13 | K11: 5.73 | L11: 6.13 | M11: 6.62 | N11: 7.11 | O11: 7.58
A12: AFRI_NORT | B12: TRA_OT_RAI | C12: 0.02 | E12: 0.03 | F12: 0.02 | G12: 0.17 | H12: 0.08 | I12: 0.27 | J12: 0.26 | K12: 0.26 | L12: 0.25 | M12: 0.25 | N12: 0.25 | O12: 0.25
A13: AFRI_NORT | B13: TRA_OT_SHIP_NAT | C13: 0.66 | D13: 0.82 | E13: 1.64 | F13: 0.96 | G13: 1.14 | H13: 0.53 | I13: 0.58 | J13: 0.69 | K13: 0.78 | L13: 0.85 | M13: 0.89 | N13: 0.9
A14: AFRI_NORT | B14: TRA_OT_OTHER | C14: 0 | D14: 0.01 | E14: 0.01 | F14: 0.01 | G14: 0.01 | H14: 0.01 | I14: 0.01 | J14: 0.01 | K14: 0.01 | L14: 0.01 | M14: 0.02 | N14: 0.02 | O14: 0.02
A15: AFRI_NORT | B15: SUM | C15: 4.14 | D15: 4.13 | E15: 6.93 | F15: 9.01 | G15: 10.77 | H15: 8.69 | I15: 11.76 | J15: 11.64 | K15: 10.98 | L15: 11.49 | M15: 12.14 | N15: 12.42 | O15: 11.78
A16: AFRI_WEST | B16: TRA_OTH
A17: AFRI_WEST | B17: TRA_OT_CNS | C17: 0.42 | D17: 0.6 | E17: 0.8 | F17: 0.91 | G17: 1.35 | H17: 2.02 | I17: 3.3 | J17: 4.06 | K17: 4.73 | L17: 5.59 | M17: 6.6 | N17: 7.68 | O17: 8.81
A18: AFRI_WEST | B18: TRA_OT_AGR | C18: 0.38 | D18: 0.51 | E18: 0.8 | F18: 0.62 | G18: 0.88 | H18: 1.41 | I18: 0.44 | J18: 0.46 | K18: 0.47 | L18: 0.48 | M18: 0.48 | N18: 0.47 | O18: 0.46
A19: AFRI_WEST | B19: TRA_OT_RAI | C19: 0.34 | D19: 0.21 | E19: 0.29 | F19: 0.25 | G19: 0.25 | H19: 0.55 | I19: 0.69 | J19: 0.8 | K19: 0.97 | L19: 1.16 | M19: 1.39 | N19: 1.65 | O19: 1.92
A20: AFRI_WEST | B20: TRA_OT_SHIP_NAT | E20: 0.31 | F20: 0.32 | G20: 0.38 | H20: 0.82 | I20: 0.88 | J20: 0.93 | K20: 1.02 | L20: 1.13 | M20: 1.24 | N20: 1.34 | O20: 1.44
A21: AFRI_WEST | B21: TRA_OT_OTHER | C21: 0 | D21: 0 | E21: 0.11 | F21: 0.2 | G21: 0.01 | H21: 0.01 | I21: 0 | J21: 0 | K21: 0 | L21: 0 | M21: 0 | N21: 0.01 | O21: 0.01
A22: AFRI_WEST | B22: SUM | C22: 1.14 | D22: 1.33 | E22: 2.31 | F22: 2.3 | G22: 2.86 | H22: 4.8 | I22: 5.32 | J22: 6.25 | K22: 7.2 | L22: 8.36 | M22: 9.72 | N22: 11.15 | O22: 12.64
A23: ASIA_STAN | B23: TRA_OTH
A24: ASIA_STAN | B24: TRA_OT_CNS | C24: 3.51 | D24: 2.42 | E24: 1.14 | F24: 1.26 | G24: 0.49 | H24: 1.96 | I24: 1.53 | J24: 1.6 | K24: 1.75 | L24: 1.83 | M24: 1.97 | N24: 1.94 | O24: 1.87
A25: ASIA_STAN | B25: TRA_OT_AGR | C25: 1.82 | D25: 1.26 | E25: 0.96 | F25: 1.05 | G25: 0.8 | H25: 0.92 | I25: 0.58 | J25: 0.67 | K25: 0.74 | L25: 0.72 | M25: 0.68 | N25: 0.64 | O25: 0.59
A26: ASIA_STAN | B26: TRA_OT_RAI | C26: 0.86 | D26: 0.59 | E26: 0.52 | F26: 0.58 | G26: 0.37 | H26: 0.16 | I26: 0.26 | J26: 0.28 | K26: 0.31 | L26: 0.33 | M26: 0.34 | N26: 0.34 | O26: 0.33
A27: ASIA_STAN | B27: TRA_OT_SHIP_NAT | G27: 0.03 | H27: 0.66
A28: ASIA_STAN | B28: TRA_OT_OTHER | C28: 0 | D28: 0 | E28: 0 | F28: 0 | G28: 0 | H28: 0 | I28: 0.01 | J28: 0.01 | K28: 0.01 | L28: 0.01 | M28: 0.01 | N28: 0.01 | O28: 0.01
A29: ASIA_STAN | B29: SUM | C29: 6.19 | D29: 4.28 | E29: 2.62 | F29: 2.89 | G29: 1.69 | H29: 3.7 | I29: 2.38 | J29: 2.57 | K29: 2.81 | L29: 2.88 | M29: 3 | N29: 2.93 | O29: 2.81
A30: BRAZ_WHOL | B30: TRA_OTH
A31: BRAZ_WHOL | B31: TRA_OT_CNS | C31: 0.25 | D31: 0.37 | E31: 0.39 | F31: 0.41 | G31: 0.51 | H31: 0.7 | I31: 0.51 | J31: 0.48 | K31: 0.42 | L31: 0.45 | M31: 0.5 | N31: 0.49 | O31: 0.48
A32: BRAZ_WHOL | B32: TRA_OT_AGR | C32: 5.6 | D32: 7.38 | E32: 7.69 | F32: 8.22 | G32: 9.97 | H32: 10.92 | I32: 11.64 | J32: 12.16 | K32: 12.74 | L32: 13.08 | M32: 13.14 | N32: 12.74 | O32: 12.11
A33: BRAZ_WHOL | B33: TRA_OT_RAI | C33: 0.98 | D33: 0.82 | E33: 0.75 | F33: 1.06 | G33: 1.72 | H33: 1.82 | I33: 1.8 | J33: 1.83 | K33: 1.95 | L33: 2.07 | M33: 2.15 | N33: 2.16 | O33: 2.08
A34: BRAZ_WHOL | B34: TRA_OT_SHIP_NAT | E34: 2 | F34: 2.46 | G34: 2.96 | H34: 2.07 | I34: 1.44 | J34: 1.32 | K34: 1.14 | L34: 0.94 | M34: 0.73 | N34: 0.52 | O34: 0.32
A35: BRAZ_WHOL | B35: TRA_OT_OTHER | C35: 0.01 | D35: 0.01 | E35: 0.01 | F35: 0.01 | G35: 0.01 | H35: 0.02 | I35: 0.01 | J35: 0.01 | K35: 0.02 | L35: 0.02 | M35: 0.02 | N35: 0.02 | O35: 0.03
A36: BRAZ_WHOL | B36: SUM | C36: 6.84 | D36: 8.58 | E36: 10.84 | F36: 12.16 | G36: 15.16 | H36: 15.52 | I36: 15.4 | J36: 15.79 | K36: 16.26 | L36: 16.57 | M36: 16.53 | N36: 15.93 | O36: 15.01
A37: CANA_WHOL | B37: TRA_OTH
A38: CANA_WHOL | B38: TRA_OT_CNS | C38: 2.57 | D38: 2.65 | E38: 3.41 | F38: 2.18 | G38: 2.25 | H38: 1.73 | I38: 3.54 | J38: 2.03 | K38: 0.9 | L38: 0.54 | M38: 0.52 | N38: 0.5 | O38: 0.48
A39: CANA_WHOL | B39: TRA_OT_AGR | C39: 3.21 | D39: 4.01 | E39: 4.54 | F39: 3.72 | G39: 3.28 | H39: 2.95 | I39: 3.55 | J39: 2.2 | K39: 1.04 | L39: 0.54 | M39: 0.53 | N39: 0.51 | O39: 0.49
A40: CANA_WHOL | B40: TRA_OT_RAI | C40: 3.79 | D40: 3.42 | E40: 3.52 | F40: 3.36 | G40: 3.03 | H40: 2.71 | I40: 1.61 | J40: 0.9 | K40: 0.45 | L40: 0.08 | M40: 0.01 | N40: 0.01 | O40: 0.01
...

Sheet Non-road BC
A1: PM PM_BC emissions from non-road transport
A3: Pollutant: PM (PM Fraction: PM_BC)
A4: Scenario: ECLIPSE_V6b_CLE_base
A5: Region: All EMF Regions
A6: UserID: jm110
A7: Unit: kt PM
A10: Region | B10: [kt/yr] | C10: 1990 | D10: 1995 | E10: 2000 | F10: 2005 | G10: 2010 | H10: 2015 | I10: 2020 | J10: 2025 | K10: 2030 | L10: 2035 | M10: 2040 | N10: 2045 | O10: 2050
A11: AFRI_EAST | B11: TRA_OTH
A12: AFRI_EAST | B12: TRA_OT_CNS | C12: 0.29 | D12: 0.42 | E12: 0.47 | F12: 0.58 | G12: 0.68 | H12: 1.43 | I12: 1.98 | J12: 2.23 | K12: 2.6 | L12: 3.07 | M12: 3.63 | N12: 4.22 | O12: 4.84
A13: AFRI_EAST | B13: TRA_OT_AGR | C13: 0.2 | D13: 0.27 | E13: 0.42 | F13: 0.57 | G13: 0.36 | H13: 0.45 | I13: 0.14 | J13: 0.14 | K13: 0.15 | L13: 0.15 | M13: 0.15 | N13: 0.15 | O13: 0.15
A14: AFRI_EAST | B14: TRA_OT_RAI | C14: 0.08 | D14: 0.05 | E14: 0.05 | F14: 0.06 | G14: 0.05 | H14: 0.12 | I14: 0.16 | J14: 0.18 | K14: 0.22 | L14: 0.26 | M14: 0.31 | N14: 0.37 | O14: 0.44
A15: AFRI_EAST | B15: TRA_OT_SHIP_NAT
A16: AFRI_EAST | B16: TRA_OT_OTHER | C16: 0 | D16: 0 | E16: 0 | F16: 0 | G16: 0.01 | H16: 0.01 | I16: 0 | J16: 0 | K16: 0 | L16: 0 | M16: 0 | N16: 0.01 | O16: 0.01
A17: AFRI_EAST | B17: SUM | C17: 0.57 | D17: 0.74 | E17: 0.94 | F17: 1.21 | G17: 1.1 | H17: 2.01 | I17: 2.28 | J17: 2.56 | K17: 2.97 | L17: 3.49 | M17: 4.1 | N17: 4.75 | O17: 5.43
A18: AFRI_NORT | B18: TRA_OTH
A19: AFRI_NORT | B19: TRA_OT_CNS | C19: 2.67 | D19: 2.2 | E19: 3.89 | F19: 3.42 | G19: 3.99 | H19: 4.69 | I19: 6.46 | J19: 5.54 | K19: 4.2 | L19: 4.25 | M19: 4.37 | N19: 4.15 | O19: 3.93
A20: AFRI_NORT | B20: TRA_OT_AGR | C20: 0.79 | D20: 1.11 | E20: 1.37 | F20: 4.6 | G20: 5.46 | H20: 3.38 | I20: 4.44 | J20: 5.13 | K20: 5.73 | L20: 6.13 | M20: 6.62 | N20: 7.11 | O20: 7.58
A21: AFRI_NORT | B21: TRA_OT_RAI | C21: 0.02 | E21: 0.03 | F21: 0.02 | G21: 0.17 | H21: 0.08 | I21: 0.27 | J21: 0.26 | K21: 0.26 | L21: 0.25 | M21: 0.25 | N21: 0.25 | O21: 0.25
A22: AFRI_NORT | B22: TRA_OT_SHIP_NAT | C22: 0.66 | D22: 0.82 | E22: 1.64 | F22: 0.96 | G22: 1.14 | H22: 0.53 | I22: 0.58 | J22: 0.69 | K22: 0.78 | L22: 0.85 | M22: 0.89 | N22: 0.9
A23: AFRI_NORT | B23: TRA_OT_OTHER | C23: 0 | D23: 0.01 | E23: 0.01 | F23: 0.01 | G23: 0.01 | H23: 0.01 | I23: 0.01 | J23: 0.01 | K23: 0.01 | L23: 0.01 | M23: 0.02 | N23: 0.02 | O23: 0.02
A24: AFRI_NORT | B24: SUM | C24: 4.14 | D24: 4.13 | E24: 6.93 | F24: 9.01 | G24: 10.77 | H24: 8.69 | I24: 11.76 | J24: 11.64 | K24: 10.98 | L24: 11.49 | M24: 12.14 | N24: 12.42 | O24: 11.78
A25: AFRI_WEST | B25: TRA_OTH
A26: AFRI_WEST | B26: TRA_OT_CNS | C26: 0.42 | D26: 0.6 | E26: 0.8 | F26: 0.91 | G26: 1.35 | H26: 2.02 | I26: 3.3 | J26: 4.06 | K26: 4.73 | L26: 5.59 | M26: 6.6 | N26: 7.68 | O26: 8.81
A27: AFRI_WEST | B27: TRA_OT_AGR | C27: 0.38 | D27: 0.51 | E27: 0.8 | F27: 0.62 | G27: 0.88 | H27: 1.41 | I27: 0.44 | J27: 0.46 | K27: 0.47 | L27: 0.48 | M27: 0.48 | N27: 0.47 | O27: 0.46
A28: AFRI_WEST | B28: TRA_OT_RAI | C28: 0.34 | D28: 0.21 | E28: 0.29 | F28: 0.25 | G28: 0.25 | H28: 0.55 | I28: 0.69 | J28: 0.8 | K28: 0.97 | L28: 1.16 | M28: 1.39 | N28: 1.65 | O28: 1.92
A29: AFRI_WEST | B29: TRA_OT_SHIP_NAT | E29: 0.31 | F29: 0.32 | G29: 0.38 | H29: 0.82 | I29: 0.88 | J29: 0.93 | K29: 1.02 | L29: 1.13 | M29: 1.24 | N29: 1.34 | O29: 1.44
A30: AFRI_WEST | B30: TRA_OT_OTHER | C30: 0 | D30: 0 | E30: 0.11 | F30: 0.2 | G30: 0.01 | H30: 0.01 | I30: 0 | J30: 0 | K30: 0 | L30: 0 | M30: 0 | N30: 0.01 | O30: 0.01
A31: AFRI_WEST | B31: SUM | C31: 1.14 | D31: 1.33 | E31: 2.31 | F31: 2.3 | G31: 2.86 | H31: 4.8 | I31: 5.32 | J31: 6.25 | K31: 7.2 | L31: 8.36 | M31: 9.72 | N31: 11.15 | O31: 12.64
A32: ASIA_STAN | B32: TRA_OTH
A33: ASIA_STAN | B33: TRA_OT_CNS | C33: 3.51 | D33: 2.42 | E33: 1.14 | F33: 1.26 | G33: 0.49 | H33: 1.96 | I33: 1.53 | J33: 1.6 | K33: 1.75 | L33: 1.83 | M33: 1.97 | N33: 1.94 | O33: 1.87
A34: ASIA_STAN | B34: TRA_OT_AGR | C34: 1.82 | D34: 1.26 | E34: 0.96 | F34: 1.05 | G34: 0.8 | H34: 0.92 | I34: 0.58 | J34: 0.67 | K34: 0.74 | L34: 0.72 | M34: 0.68 | N34: 0.64 | O34: 0.59
A35: ASIA_STAN | B35: TRA_OT_RAI | C35: 0.86 | D35: 0.59 | E35: 0.52 | F35: 0.58 | G35: 0.37 | H35: 0.16 | I35: 0.26 | J35: 0.28 | K35: 0.31 | L35: 0.33 | M35: 0.34 | N35: 0.34 | O35: 0.33
A36: ASIA_STAN | B36: TRA_OT_SHIP_NAT | G36: 0.03 | H36: 0.66
A37: ASIA_STAN | B37: TRA_OT_OTHER | C37: 0 | D37: 0 | E37: 0 | F37: 0 | G37: 0 | H37: 0 | I37: 0.01 | J37: 0.01 | K37: 0.01 | L37: 0.01 | M37: 0.01 | N37: 0.01 | O37: 0.01
A38: ASIA_STAN | B38: SUM | C38: 6.19 | D38: 4.28 | E38: 2.62 | F38: 2.89 | G38: 1.69 | H38: 3.7 | I38: 2.38 | J38: 2.57 | K38: 2.81 | L38: 2.88 | M38: 3 | N38: 2.93 | O38: 2.81
A39: BRAZ_WHOL | B39: TRA_OTH
A40: BRAZ_WHOL | B40: TRA_OT_CNS | C40: 0.25 | D40: 0.37 | E40: 0.39 | F40: 0.41 | G40: 0.51 | H40: 0.7 | I40: 0.51 | J40: 0.48 | K40: 0.42 | L40: 0.45 | M40: 0.5 | N40: 0.49 | O40: 0.48
A41: BRAZ_WHOL | B41: TRA_OT_AGR | C41: 5.6 | D41: 7.38 | E41: 7.69 | F41: 8.22 | G41: 9.97 | H41: 10.92 | I41: 11.64 | J41: 12.16 | K41: 12.74 | L41: 13.08 | M41: 13.14 | N41: 12.74 | O41: 12.11
A42: BRAZ_WHOL | B42: TRA_OT_RAI | C42: 0.98 | D42: 0.82 | E42: 0.75 | F42: 1.06 | G42: 1.72 | H42: 1.82 | I42: 1.8 | J42: 1.83 | K42: 1.95 | L42: 2.07 | M42: 2.15 | N42: 2.16 | O42: 2.08
A43: BRAZ_WHOL | B43: TRA_OT_SHIP_NAT | E43: 2 | F43: 2.46 | G43: 2.96 | H43: 2.07 | I43: 1.44 | J43: 1.32 | K43: 1.14 | L43: 0.94 | M43: 0.73 | N43: 0.52 | O43: 0.32
...

Sheet Non-road CH4_CLEAN
A1: Region | B1: Sector | C1: 1990 | D1: 1995 | E1: 2000 | F1: 2005 | G1: 2010 | H1: 2015 | I1: 2020 | J1: 2025 | K1: 2030 | L1: 2035 | M1: 2040 | N1: 2045 | O1: 2050
A2: AFRI_EAST | B2: TRA_OTH
A3: AFRI_EAST | B3: TRA_OT_CNS | C3: 0.02 | D3: 0.03 | E3: 0.03 | F3: 0.04 | G3: 0.05 | H3: 0.1 | I3: 0.14 | J3: 0.15 | K3: 0.18 | L3: 0.21 | M3: 0.25 | N3: 0.29 | O3: 0.33
A4: AFRI_EAST | B4: TRA_OT_AGR | C4: 0.02 | D4: 0.02 | E4: 0.03 | F4: 0.05 | G4: 0.03 | H4: 0.04 | I4: 0.01 | J4: 0.01 | K4: 0.01 | L4: 0.01 | M4: 0.01 | N4: 0.01 | O4: 0.01
A5: AFRI_EAST | B5: TRA_OT_RAI | C5: 0.01 | D5: 0 | E5: 0 | F5: 0.01 | G5: 0 | H5: 0.01 | I5: 0.01 | J5: 0.02 | K5: 0.02 | L5: 0.02 | M5: 0.03 | N5: 0.03 | O5: 0.04
A6: AFRI_EAST | B6: TRA_OT_SHIP_NAT
A7: AFRI_EAST | B7: TRA_OT_OTHER | C7: 0.01 | D7: 0.01 | E7: 0.01 | F7: 0.01 | G7: 0.02 | H7: 0.02 | I7: 0.01 | J7: 0.01 | K7: 0.01 | L7: 0.01 | M7: 0.01 | N7: 0.02 | O7: 0.02
A8: AFRI_EAST | B8: SUM | C8: 0.05 | D8: 0.06 | E8: 0.08 | F8: 0.11 | G8: 0.1 | H8: 0.17 | I8: 0.17 | J8: 0.19 | K8: 0.22 | L8: 0.26 | M8: 0.31 | N8: 0.35 | O8: 0.4
A9: AFRI_NORT | B9: TRA_OTH
A10: AFRI_NORT | B10: TRA_OT_CNS | C10: 0.18 | D10: 0.15 | E10: 0.27 | F10: 0.24 | G10: 0.28 | H10: 0.32 | I10: 0.45 | J10: 0.38 | K10: 0.29 | L10: 0.29 | M10: 0.3 | N10: 0.29 | O10: 0.27
A11: AFRI_NORT | B11: TRA_OT_AGR | C11: 0.06 | D11: 0.09 | E11: 0.11 | F11: 0.37 | G11: 0.44 | H11: 0.27 | I11: 0.36 | J11: 0.41 | K11: 0.46 | L11: 0.49 | M11: 0.53 | N11: 0.57 | O11: 0.61
A12: AFRI_NORT | B12: TRA_OT_RAI | C12: 0 | E12: 0 | F12: 0 | G12: 0.02 | H12: 0.01 | I12: 0.02 | J12: 0.02 | K12: 0.02 | L12: 0.02 | M12: 0.02 | N12: 0.02 | O12: 0.02
A13: AFRI_NORT | B13: TRA_OT_SHIP_NAT | C13: 0.09 | D13: 0.11 | E13: 0.22 | F13: 0.13 | G13: 0.16 | H13: 0.07 | I13: 0.08 | J13: 0.1 | K13: 0.11 | L13: 0.12 | M13: 0.13 | N13: 0.13
A14: AFRI_NORT | B14: TRA_OT_OTHER | C14: 0 | D14: 0.01 | E14: 0.01 | F14: 0.01 | G14: 0.01 | H14: 0.01 | I14: 0.02 | J14: 0.02 | K14: 0.02 | L14: 0.02 | M14: 0.03 | N14: 0.03 | O14: 0.03
A15: AFRI_NORT | B15: SUM | C15: 0.34 | D15: 0.36 | E15: 0.62 | F15: 0.75 | G15: 0.9 | H15: 0.69 | I15: 0.93 | J15: 0.94 | K15: 0.91 | L15: 0.96 | M15: 1.01 | N15: 1.04 | O15: 0.93
A16: AFRI_WEST | B16: TRA_OTH
A17: AFRI_WEST | B17: TRA_OT_CNS | C17: 0.03 | D17: 0.04 | E17: 0.06 | F17: 0.06 | G17: 0.09 | H17: 0.14 | I17: 0.23 | J17: 0.28 | K17: 0.33 | L17: 0.39 | M17: 0.46 | N17: 0.53 | O17: 0.61
A18: AFRI_WEST | B18: TRA_OT_AGR | C18: 0.03 | D18: 0.04 | E18: 0.06 | F18: 0.05 | G18: 0.07 | H18: 0.11 | I18: 0.04 | J18: 0.04 | K18: 0.04 | L18: 0.04 | M18: 0.04 | N18: 0.04 | O18: 0.04
A19: AFRI_WEST | B19: TRA_OT_RAI | C19: 0.03 | D19: 0.02 | E19: 0.03 | F19: 0.02 | G19: 0.02 | H19: 0.05 | I19: 0.06 | J19: 0.07 | K19: 0.09 | L19: 0.11 | M19: 0.13 | N19: 0.15 | O19: 0.18
A20: AFRI_WEST | B20: TRA_OT_SHIP_NAT | E20: 0.05 | F20: 0.05 | G20: 0.06 | H20: 0.13 | I20: 0.14 | J20: 0.15 | K20: 0.17 | L20: 0.18 | M20: 0.2 | N20: 0.22 | O20: 0.23
A21: AFRI_WEST | B21: TRA_OT_OTHER | C21: 0.01 | D21: 0.01 | E21: 0.08 | F21: 0.13 | G21: 0.02 | H21: 0.02 | I21: 0.01 | J21: 0.01 | K21: 0.01 | L21: 0.01 | M21: 0.01 | N21: 0.02 | O21: 0.02
A22: AFRI_WEST | B22: SUM | C22: 0.1 | D22: 0.11 | E22: 0.27 | F22: 0.32 | G22: 0.27 | H22: 0.46 | I22: 0.48 | J22: 0.55 | K22: 0.63 | L22: 0.73 | M22: 0.84 | N22: 0.96 | O22: 1.08
A23: ASIA_STAN | B23: TRA_OTH
A24: ASIA_STAN | B24: TRA_OT_CNS | C24: 0.24 | D24: 0.17 | E24: 0.08 | F24: 0.09 | G24: 0.03 | H24: 0.14 | I24: 0.11 | J24: 0.11 | K24: 0.12 | L24: 0.13 | M24: 0.14 | N24: 0.13 | O24: 0.13
A25: ASIA_STAN | B25: TRA_OT_AGR | C25: 0.15 | D25: 0.1 | E25: 0.08 | F25: 0.08 | G25: 0.06 | H25: 0.07 | I25: 0.05 | J25: 0.05 | K25: 0.06 | L25: 0.06 | M25: 0.05 | N25: 0.05 | O25: 0.05
A26: ASIA_STAN | B26: TRA_OT_RAI | C26: 0.08 | D26: 0.06 | E26: 0.05 | F26: 0.05 | G26: 0.03 | H26: 0.02 | I26: 0.02 | J26: 0.03 | K26: 0.03 | L26: 0.03 | M26: 0.03 | N26: 0.03 | O26: 0.03
A27: ASIA_STAN | B27: TRA_OT_SHIP_NAT | G27: 0.01 | H27: 0.08
A28: ASIA_STAN | B28: TRA_OT_OTHER | C28: 0 | D28: 0 | E28: 0 | F28: 0 | G28: 0.01 | H28: 0 | I28: 0.01 | J28: 0.01 | K28: 0.01 | L28: 0.01 | M28: 0.01 | N28: 0.01 | O28: 0.01
A29: ASIA_STAN | B29: SUM | C29: 0.47 | D29: 0.33 | E29: 0.21 | F29: 0.23 | G29: 0.14 | H29: 0.31 | I29: 0.19 | J29: 0.2 | K29: 0.22 | L29: 0.23 | M29: 0.23 | N29: 0.23 | O29: 0.22
A30: BRAZ_WHOL | B30: TRA_OTH
A31: BRAZ_WHOL | B31: TRA_OT_CNS | C31: 0.02 | D31: 0.03 | E31: 0.03 | F31: 0.03 | G31: 0.04 | H31: 0.05 | I31: 0.04 | J31: 0.03 | K31: 0.03 | L31: 0.03 | M31: 0.03 | N31: 0.03 | O31: 0.03
A32: BRAZ_WHOL | B32: TRA_OT_AGR | C32: 0.45 | D32: 0.59 | E32: 0.62 | F32: 0.66 | G32: 0.8 | H32: 0.88 | I32: 0.94 | J32: 0.98 | K32: 1.03 | L32: 1.05 | M32: 1.06 | N32: 1.03 | O32: 0.97
